Workbook

Sheet River (Original Data)
B1: Jan 9a-4p | C1: Jan 4a-9a 4p-9p | D1: Jan 9p-4a | E1: Feb 9a-4p | F1: Feb 4a-9a 4p-9p | G1: Feb 9p-4a | H1: Mar 9a-4p | I1: Mar 4a-9a 4p-9p | J1: Mar 9p-4a | K1: Apr 9a-4p | L1: Apr 4a-9a 4p-9p | M1: Apr 9p-4a | N1: May 9a-4p | O1: May 4a-9a 4p-9p | P1: May 9p-4a | Q1: Jun 9a-4p | R1: Jun 4a-9a 4p-9p | S1: Jun 9p-4a | T1: Jul 9a-4p | U1: Jul 4a-9a 4p-9p | V1: Jul 9p-4a | W1: Aug 9a-4p | X1: Aug 4a-9a 4p-9p | Y1: Aug 9p-4a | Z1: Sep 9a-4p | AA1: Sep 4a-9a 4p-9p | AB1: Sep 9p-4a | AC1: Oct 9a-4p | AD1: Oct 4a-9a 4p-9p | AE1: Oct 9p-4a | AF1: Nov 9a-4p | AG1: Nov 4a-9a 4p-9p | AH1: Nov 9p-4a | AI1: Dec 9a-4p | AJ1: Dec 4a-9a 4p-9p | AK1: Dec 9p-4a
A2: Angelfish | B2: 0 | C2: 0 | D2: 0 | E2: 0 | F2: 0 | G2: 0 | H2: 0 | I2: 0 | J2: 0 | K2: 0 | L2: 0 | M2: 0 | N2: 0 | O2: 3 | P2: 3 | Q2: 0 | R2: 3 | S2: 3 | T2: 0 | U2: 2 | V2: 2 | W2: 0 | X2: 2 | Y2: 2 | Z2: 0 | AA2: 2 | AB2: 2 | AC2: 0 | AD2: 5 | AE2: 5 | AF2: 0 | AG2: 0 | AH2: 0 | AI2: 0 | AJ2: 0 | AK2: 0
A3: Arapaima | B3: 0 | C3: 0 | D3: 0 | E3: 0 | F3: 0 | G3: 0 | H3: 0 | I3: 0 | J3: 0 | K3: 0 | L3: 0 | M3: 0 | N3: 0 | O3: 0 | P3: 0 | Q3: 0 | R3: 1 | S3: 1 | T3: 0 | U3: 1 | V3: 1 | W3: 0 | X3: 1 | Y3: 1 | Z3: 0 | AA3: 1 | AB3: 1 | AC3: 0 | AD3: 0 | AE3: 0 | AF3: 0 | AG3: 0 | AH3: 0 | AI3: 0 | AJ3: 0 | AK3: 0
A4: Arowana | B4: 0 | C4: 0 | D4: 0 | E4: 0 | F4: 0 | G4: 0 | H4: 0 | I4: 0 | J4: 0 | K4: 0 | L4: 0 | M4: 0 | N4: 0 | O4: 0 | P4: 0 | Q4: 0 | R4: 1 | S4: 2 | T4: 0 | U4: 1 | V4: 2 | W4: 0 | X4: 1 | Y4: 2 | Z4: 0 | AA4: 1 | AB4: 2 | AC4: 0 | AD4: 0 | AE4: 0 | AF4: 0 | AG4: 0 | AH4: 0 | AI4: 0 | AJ4: 0 | AK4: 0
A5: Betta | B5: 0 | C5: 0 | D5: 0 | E5: 0 | F5: 0 | G5: 0 | H5: 0 | I5: 0 | J5: 0 | K5: 0 | L5: 0 | M5: 0 | N5: 2 | O5: 0 | P5: 0 | Q5: 1 | R5: 0 | S5: 0 | T5: 1 | U5: 0 | V5: 0 | W5: 1 | X5: 0 | Y5: 0 | Z5: 2 | AA5: 0 | AB5: 0 | AC5: 4 | AD5: 0 | AE5: 0 | AF5: 0 | AG5: 0 | AH5: 0 | AI5: 0 | AJ5: 0 | AK5: 0
A6: Bitterling | B6: 15 | C6: 15 | D6: 15 | E6: 15 | F6: 15 | G6: 15 | H6: 14 | I6: 12 | J6: 12 | K6: 0 | L6: 0 | M6: 0 | N6: 0 | O6: 0 | P6: 0 | Q6: 0 | R6: 0 | S6: 0 | T6: 0 | U6: 0 | V6: 0 | W6: 0 | X6: 0 | Y6: 0 | Z6: 0 | AA6: 0 | AB6: 0 | AC6: 0 | AD6: 0 | AE6: 0 | AF6: 17 | AG6: 16 | AH6: 16 | AI6: 13 | AJ6: 13 | AK6: 13
A7: Black Bass | B7: 11 | C7: 11 | D7: 11 | E7: 11 | F7: 11 | G7: 11 | H7: 11 | I7: 10 | J7: 10 | K7: 9 | L7: 9 | M7: 9 | N7: 10 | O7: 9 | P7: 8 | Q7: 10 | R7: 10 | S7: 9 | T7: 8 | U7: 8 | V7: 7 | W7: 9 | X7: 8 | Y7: 8 | Z7: 5 | AA7: 4 | AB7: 4 | AC7: 9 | AD7: 11 | AE7: 10 | AF7: 9 | AG7: 10 | AH7: 11 | AI7: 12 | AJ7: 12 | AK7: 12
A8: Blueguill | B8: 8 | C8: 0 | D8: 0 | E8: 8 | F8: 0 | G8: 0 | H8: 9 | I8: 0 | J8: 0 | K8: 9 | L8: 0 | M8: 0 | N8: 8 | O8: 0 | P8: 0 | Q8: 8 | R8: 0 | S8: 0 | T8: 7 | U8: 0 | V8: 0 | W8: 7 | X8: 0 | Y8: 0 | Z8: 6 | AA8: 0 | AB8: 0 | AC8: 8 | AD8: 0 | AE8: 0 | AF8: 10 | AG8: 0 | AH8: 0 | AI8: 7 | AJ8: 0 | AK8: 0
A9: Crucian Carp | B9: 12 | C9: 12 | D9: 12 | E9: 12 | F9: 12 | G9: 12 | H9: 11 | I9: 10 | J9: 10 | K9: 11 | L9: 11 | M9: 10 | N9: 9 | O9: 9 | P9: 7 | Q9: 10 | R9: 9 | S9: 8 | T9: 9 | U9: 9 | V9: 8 | W9: 9 | X9: 9 | Y9: 8 | Z9: 4 | AA9: 4 | AB9: 4 | AC9: 9 | AD9: 9 | AE9: 8 | AF9: 11 | AG9: 12 | AH9: 12 | AI9: 11 | AJ9: 12 | AK9: 12
A10: Dace | B10: 0 | C10: 8 | D10: 8 | E10: 0 | F10: 8 | G10: 8 | H10: 0 | I10: 9 | J10: 9 | K10: 0 | L10: 10 | M10: 10 | N10: 0 | O10: 9 | P10: 8 | Q10: 0 | R10: 7 | S10: 7 | T10: 0 | U10: 7 | V10: 7 | W10: 0 | X10: 8 | Y10: 8 | Z10: 0 | AA10: 3 | AB10: 3 | AC10: 0 | AD10: 8 | AE10: 8 | AF10: 0 | AG10: 10 | AH10: 10 | AI10: 0 | AJ10: 9 | AK10: 9
A11: Dorado | B11: 0 | C11: 0 | D11: 0 | E11: 0 | F11: 0 | G11: 0 | H11: 0 | I11: 0 | J11: 0 | K11: 0 | L11: 0 | M11: 0 | N11: 0 | O11: 0 | P11: 0 | Q11: 1 | R11: 2 | S11: 0 | T11: 1 | U11: 2 | V11: 0 | W11: 1 | X11: 2 | Y11: 0 | Z11: 2 | AA11: 2 | AB11: 0 | AC11: 0 | AD11: 0 | AE11: 0 | AF11: 0 | AG11: 0 | AH11: 0 | AI11: 0 | AJ11: 0 | AK11: 0
A12: Freshwater Goby | B12: 0 | C12: 4 | D12: 4 | E12: 0 | F12: 4 | G12: 4 | H12: 0 | I12: 3 | J12: 3 | K12: 0 | L12: 3 | M12: 3 | N12: 0 | O12: 3 | P12: 3 | Q12: 0 | R12: 3 | S12: 3 | T12: 0 | U12: 3 | V12: 3 | W12: 0 | X12: 3 | Y12: 3 | Z12: 0 | AA12: 3 | AB12: 2 | AC12: 0 | AD12: 5 | AE12: 5 | AF12: 0 | AG12: 3 | AH12: 3 | AI12: 0 | AJ12: 4 | AK12: 4
A13: Guppy | B13: 0 | C13: 0 | D13: 0 | E13: 0 | F13: 0 | G13: 0 | H13: 0 | I13: 0 | J13: 0 | K13: 3 | L13: 0 | M13: 0 | N13: 2 | O13: 0 | P13: 0 | Q13: 2 | R13: 0 | S13: 0 | T13: 2 | U13: 0 | V13: 0 | W13: 2 | X13: 0 | Y13: 0 | Z13: 2 | AA13: 0 | AB13: 0 | AC13: 3 | AD13: 0 | AE13: 0 | AF13: 3 | AG13: 0 | AH13: 0 | AI13: 0 | AJ13: 0 | AK13: 0
... A32: Stone | B32: 2 | C32: 2 | D32: 2 | E32: 2 | F32: 2 | G32: 2 | H32: 2 | I32: 2 | J32: 2 | K32: 2 | L32: 2 | M32: 2 | N32: 2 | O32: 2 | P32: 2 | Q32: 2 | R32: 2 | S32: 2 | T32: 2 | U32: 2 | V32: 2 | W32: 2 | X32: 2 | Y32: 2 | Z32: 2 | AA32: 2 | AB32: 2 | AC32: 2 | AD32: 2 | AE32: 2 | AF32: 2 | AG32: 2 | AH32: 2 | AI32: 2 | AJ32: 2 | AK32: 2
B33: Jan 9a-4p | C33: Jan 4a-9a 4p-9p | D33: Jan 9p-4a | E33: Feb 9a-4p | F33: Feb 4a-9a 4p-9p | G33: Feb 9p-4a | H33: Mar 9a-4p | I33: Mar 4a-9a 4p-9p | J33: Mar 9p-4a | K33: Apr 9a-4p | L33: Apr 4a-9a 4p-9p | M33: Apr 9p-4a | N33: May 9a-4p | O33: May 4a-9a 4p-9p | P33: May 9p-4a | Q33: Jun 9a-4p | R33: Jun 4a-9a 4p-9p | S33: Jun 9p-4a | T33: Jul 9a-4p | U33: Jul 4a-9a 4p-9p | V33: Jul 9p-4a | W33: Aug 9a-4p | X33: Aug 4a-9a 4p-9p | Y33: Aug 9p-4a | Z33: Sep 9a-4p | AA33: Sep 4a-9a 4p-9p | AB33: Sep 9p-4a | AC33: Oct 9a-4p | AD33: Oct 4a-9a 4p-9p | AE33: Oct 9p-4a | AF33: Nov 9a-4p | AG33: Nov 4a-9a 4p-9p | AH33: Nov 9p-4a | AI33: Dec 9a-4p | AJ33: Dec 4a-9a 4p-9p | AK33: Dec 9p-4a

Sheet River (Adjusted)
B1: Jan 9a-4p | C1: Jan 4a-9a 4p-9p | D1: Jan 9p-4a | E1: Feb 9a-4p | F1: Feb 4a-9a 4p-9p | G1: Feb 9p-4a | H1: Mar 9a-4p | I1: Mar 4a-9a 4p-9p | J1: Mar 9p-4a | K1: Apr 9a-4p | L1: Apr 4a-9a 4p-9p | M1: Apr 9p-4a | N1: May 9a-4p | O1: May 4a-9a 4p-9p | P1: May 9p-4a | Q1: Jun 9a-4p | R1: Jun 4a-9a 4p-9p | S1: Jun 9p-4a | T1: Jul 9a-4p | U1: Jul 4a-9a 4p-9p | V1: Jul 9p-4a | W1: Aug 9a-4p | X1: Aug 4a-9a 4p-9p | Y1: Aug 9p-4a | Z1: Sep 9a-4p | AA1: Sep 4a-9a 4p-9p | AB1: Sep 9p-4a | AC1: Oct 9a-4p | AD1: Oct 4a-9a 4p-9p | AE1: Oct 9p-4a | AF1: Nov 9a-4p | AG1: Nov 4a-9a 4p-9p | AH1: Nov 9p-4a | AI1: Dec 9a-4p | AJ1: Dec 4a-9a 4p-9p | AK1: Dec 9p-4a | AN1: Price
A2: Angelfish | B2: {=IF( 'River (Original Data)'!B2:AK32 = "", "", 'River (Original Data)'!B2:AK32 / (MMULT(TRANSPOSE(SIGN(ROW('River (Original Data)'!B2:AK32))), N('River (Original Data)'!B2:AK32))) )} -> 0 | C2: 0 | D2: 0 | E2: 0 | F2: 0 | G2: 0 | H2: 0 | I2: 0 | J2: 0 | K2: 0 | L2: 0 | M2: 0 | N2: 0 | O2: 0.058823529 | P2: 0.06122449 | Q2: 0 | R2: 0.06122449 | S2: 0.06 | T2: 0 | U2: 0.036363636 | V2: 0.035714286 | W2: 0 | X2: 0.032786885 | Y2: 0.032258065 | Z2: 0 | AA2: 0.040816327 | AB2: 0.040816327 | AC2: 0 | AD2: 0.073529412 | AE2: 0.073529412 | AF2: 0 | AG2: 0 | AH2: 0 | AI2: 0 | AJ2: 0 | AK2: 0 | AM2: Angelfish | AN2: 3000
A3: Arapaima | B3: 0 | C3: 0 | D3: 0 | E3: 0 | F3: 0 | G3: 0 | H3: 0 | I3: 0 | J3: 0 | K3: 0 | L3: 0 | M3: 0 | N3: 0 | O3: 0 | P3: 0 | Q3: 0 | R3: 0.020408163 | S3: 0.02 | T3: 0 | U3: 0.018181818 | V3: 0.017857143 | W3: 0 | X3: 0.016393443 | Y3: 0.016129032 | Z3: 0 | AA3: 0.020408163 | AB3: 0.020408163 | AC3: 0 | AD3: 0 | AE3: 0 | AF3: 0 | AG3: 0 | AH3: 0 | AI3: 0 | AJ3: 0 | AK3: 0 | AM3: Arapaima | AN3: 10000
A4: Arowana | B4: 0 | C4: 0 | D4: 0 | E4: 0 | F4: 0 | G4: 0 | H4: 0 | I4: 0 | J4: 0 | K4: 0 | L4: 0 | M4: 0 | N4: 0 | O4: 0 | P4: 0 | Q4: 0 | R4: 0.020408163 | S4: 0.04 | T4: 0 | U4: 0.018181818 | V4: 0.035714286 | W4: 0 | X4: 0.016393443 | Y4: 0.032258065 | Z4: 0 | AA4: 0.020408163 | AB4: 0.040816327 | AC4: 0 | AD4: 0 | AE4: 0 | AF4: 0 | AG4: 0 | AH4: 0 | AI4: 0 | AJ4: 0 | AK4: 0 | AM4: Arowana | AN4: 10000
A5: Betta | B5: 0 | C5: 0 | D5: 0 | E5: 0 | F5: 0 | G5: 0 | H5: 0 | I5: 0 | J5: 0 | K5: 0 | L5: 0 | M5: 0 | N5: 0.031746032 | O5: 0 | P5: 0 | Q5: 0.016393443 | R5: 0 | S5: 0 | T5: 0.015625 | U5: 0 | V5: 0 | W5: 0.014925373 | X5: 0 | Y5: 0 | Z5: 0.034482759 | AA5: 0 | AB5: 0 | AC5: 0.054794521 | AD5: 0 | AE5: 0 | AF5: 0 | AG5: 0 | AH5: 0 | AI5: 0 | AJ5: 0 | AK5: 0 | AM5: Betta | AN5: 2500
A6: Bitterling | B6: 0.17647059 | C6: 0.18292683 | D6: 0.18292683 | E6: 0.17647059 | F6: 0.18292683 | G6: 0.18292683 | H6: 0.17283951 | I6: 0.17142857 | J6: 0.17142857 | K6: 0 | L6: 0 | M6: 0 | N6: 0 | O6: 0 | P6: 0 | Q6: 0 | R6: 0 | S6: 0 | T6: 0 | U6: 0 | V6: 0 | W6: 0 | X6: 0 | Y6: 0 | Z6: 0 | AA6: 0 | AB6: 0 | AC6: 0 | AD6: 0 | AE6: 0 | AF6: 0.22077922 | AG6: 0.21621622 | AH6: 0.21621622 | AI6: 0.15116279 | AJ6: 0.15294118 | AK6: 0.15294118 | AM6: Bitterling | AN6: 900
A7: Black Bass | B7: 0.12941176 | C7: 0.13414634 | D7: 0.13414634 | E7: 0.12941176 | F7: 0.13414634 | G7: 0.13414634 | H7: 0.13580247 | I7: 0.14285714 | J7: 0.14285714 | K7: 0.13636364 | L7: 0.16363636 | M7: 0.16071429 | N7: 0.15873016 | O7: 0.17647059 | P7: 0.16326531 | Q7: 0.16393443 | R7: 0.20408163 | S7: 0.18 | T7: 0.125 | U7: 0.14545455 | V7: 0.125 | W7: 0.13432836 | X7: 0.13114754 | Y7: 0.12903226 | Z7: 0.086206897 | AA7: 0.081632653 | AB7: 0.081632653 | AC7: 0.12328767 | AD7: 0.16176471 | AE7: 0.14705882 | AF7: 0.11688312 | AG7: 0.13513514 | AH7: 0.14864865 | AI7: 0.13953488 | AJ7: 0.14117647 | AK7: 0.14117647 | AM7: Black Bass | AN7: 400
A8: Blueguill | B8: 0.094117647 | C8: 0 | D8: 0 | E8: 0.094117647 | F8: 0 | G8: 0 | H8: 0.11111111 | I8: 0 | J8: 0 | K8: 0.13636364 | L8: 0 | M8: 0 | N8: 0.12698413 | O8: 0 | P8: 0 | Q8: 0.13114754 | R8: 0 | S8: 0 | T8: 0.109375 | U8: 0 | V8: 0 | W8: 0.10447761 | X8: 0 | Y8: 0 | Z8: 0.10344828 | AA8: 0 | AB8: 0 | AC8: 0.10958904 | AD8: 0 | AE8: 0 | AF8: 0.12987013 | AG8: 0 | AH8: 0 | AI8: 0.081395349 | AJ8: 0 | AK8: 0 | AM8: Bluegill | AN8: 180
A9: Crucian Carp | B9: 0.14117647 | C9: 0.14634146 | D9: 0.14634146 | E9: 0.14117647 | F9: 0.14634146 | G9: 0.14634146 | H9: 0.13580247 | I9: 0.14285714 | J9: 0.14285714 | K9: 0.16666667 | L9: 0.2 | M9: 0.17857143 | N9: 0.14285714 | O9: 0.17647059 | P9: 0.14285714 | Q9: 0.16393443 | R9: 0.18367347 | S9: 0.16 | T9: 0.140625 | U9: 0.16363636 | V9: 0.14285714 | W9: 0.13432836 | X9: 0.14754098 | Y9: 0.12903226 | Z9: 0.068965517 | AA9: 0.081632653 | AB9: 0.081632653 | AC9: 0.12328767 | AD9: 0.13235294 | AE9: 0.11764706 | AF9: 0.14285714 | AG9: 0.16216216 | AH9: 0.16216216 | AI9: 0.12790698 | AJ9: 0.14117647 | AK9: 0.14117647 | AM9: Crucian Carp | AN9: 160
A10: Dace | B10: 0 | C10: 0.097560976 | D10: 0.097560976 | E10: 0 | F10: 0.097560976 | G10: 0.097560976 | H10: 0 | I10: 0.12857143 | J10: 0.12857143 | K10: 0 | L10: 0.18181818 | M10: 0.17857143 | N10: 0 | O10: 0.17647059 | P10: 0.16326531 | Q10: 0 | R10: 0.14285714 | S10: 0.14 | T10: 0 | U10: 0.12727273 | V10: 0.125 | W10: 0 | X10: 0.13114754 | Y10: 0.12903226 | Z10: 0 | AA10: 0.06122449 | AB10: 0.06122449 | AC10: 0 | AD10: 0.11764706 | AE10: 0.11764706 | AF10: 0 | AG10: 0.13513514 | AH10: 0.13513514 | AI10: 0 | AJ10: 0.10588235 | AK10: 0.10588235 | AM10: Dace | AN10: 240
A11: Dorado | B11: 0 | C11: 0 | D11: 0 | E11: 0 | F11: 0 | G11: 0 | H11: 0 | I11: 0 | J11: 0 | K11: 0 | L11: 0 | M11: 0 | N11: 0 | O11: 0 | P11: 0 | Q11: 0.016393443 | R11: 0.040816327 | S11: 0 | T11: 0.015625 | U11: 0.036363636 | V11: 0 | W11: 0.014925373 | X11: 0.032786885 | Y11: 0 | Z11: 0.034482759 | AA11: 0.040816327 | AB11: 0 | AC11: 0 | AD11: 0 | AE11: 0 | AF11: 0 | AG11: 0 | AH11: 0 | AI11: 0 | AJ11: 0 | AK11: 0 | AM11: Dorado | AN11: 15000
A12: Freshwater Goby | B12: 0 | C12: 0.048780488 | D12: 0.048780488 | E12: 0 | F12: 0.048780488 | G12: 0.048780488 | H12: 0 | I12: 0.042857143 | J12: 0.042857143 | K12: 0 | L12: 0.054545455 | M12: 0.053571429 | N12: 0 | O12: 0.058823529 | P12: 0.06122449 | Q12: 0 | R12: 0.06122449 | S12: 0.06 | T12: 0 | U12: 0.054545455 | V12: 0.053571429 | W12: 0 | X12: 0.049180328 | Y12: 0.048387097 | Z12: 0 | AA12: 0.06122449 | AB12: 0.040816327 | AC12: 0 | AD12: 0.073529412 | AE12: 0.073529412 | AF12: 0 | AG12: 0.040540541 | AH12: 0.040540541 | AI12: 0 | AJ12: 0.047058824 | AK12: 0.047058824 | AM12: Freshwater Goby | AN12: 400
A13: Guppy | B13: 0 | C13: 0 | D13: 0 | E13: 0 | F13: 0 | G13: 0 | H13: 0 | I13: 0 | J13: 0 | K13: 0.045454545 | L13: 0 | M13: 0 | N13: 0.031746032 | O13: 0 | P13: 0 | Q13: 0.032786885 | R13: 0 | S13: 0 | T13: 0.03125 | U13: 0 | V13: 0 | W13: 0.029850746 | X13: 0 | Y13: 0 | Z13: 0.034482759 | AA13: 0 | AB13: 0 | AC13: 0.04109589 | AD13: 0 | AE13: 0 | AF13: 0.038961039 | AG13: 0 | AH13: 0 | AI13: 0 | AJ13: 0 | AK13: 0 | AM13: Guppy | AN13: 1300
A14: Loach | B14: 0 | C14: 0 | D14: 0 | E14: 0 | F14: 0 | G14: 0 | H14: 0.17283951 | I14: 0.18571429 | J14: 0.18571429 | K14: 0.24242424 | L14: 0.29090909 | M14: 0.28571429 | N14: 0.19047619 | O14: 0.23529412 | P14: 0.24489796 | Q14: 0 | R14: 0 | S14: 0 | T14: 0 | U14: 0 | V14: 0 | W14: 0 | X14: 0 | Y14: 0 | Z14: 0 | AA14: 0 | AB14: 0 | AC14: 0 | AD14: 0 | AE14: 0 | AF14: 0 | AG14: 0 | AH14: 0 | AI14: 0 | AJ14: 0 | AK14: 0 | AM14: Loach | AN14: 400
... A32: Stone | B32: 0.023529412 | C32: 0.024390244 | D32: 0.024390244 | E32: 0.023529412 | F32: 0.024390244 | G32: 0.024390244 | H32: 0.024691358 | I32: 0.028571429 | J32: 0.028571429 | K32: 0.03030303 | L32: 0.036363636 | M32: 0.035714286 | N32: 0.031746032 | O32: 0.039215686 | P32: 0.040816327 | Q32: 0.032786885 | R32: 0.040816327 | S32: 0.04 | T32: 0.03125 | U32: 0.036363636 | V32: 0.035714286 | W32: 0.029850746 | X32: 0.032786885 | Y32: 0.032258065 | Z32: 0.034482759 | AA32: 0.040816327 | AB32: 0.040816327 | AC32: 0.02739726 | AD32: 0.029411765 | AE32: 0.029411765 | AF32: 0.025974026 | AG32: 0.027027027 | AH32: 0.027027027 | AI32: 0.023255814 | AJ32: 0.023529412 | AK32: 0.023529412 | AM32: Stone | AN32: 10

Sheet River (Expected Prices)
B1: Jan 9a-4p | C1: Jan 4a-9a 4p-9p | D1: Jan 9p-4a | E1: Feb 9a-4p | F1: Feb 4a-9a 4p-9p | G1: Feb 9p-4a | H1: Mar 9a-4p | I1: Mar 4a-9a 4p-9p | J1: Mar 9p-4a | K1: Apr 9a-4p | L1: Apr 4a-9a 4p-9p | M1: Apr 9p-4a | N1: May 9a-4p | O1: May 4a-9a 4p-9p | P1: May 9p-4a | Q1: Jun 9a-4p | R1: Jun 4a-9a 4p-9p | S1: Jun 9p-4a | T1: Jul 9a-4p | U1: Jul 4a-9a 4p-9p | V1: Jul 9p-4a | W1: Aug 9a-4p | X1: Aug 4a-9a 4p-9p | Y1: Aug 9p-4a | Z1: Sep 9a-4p | AA1: Sep 4a-9a 4p-9p | AB1: Sep 9p-4a | AC1: Oct 9a-4p | AD1: Oct 4a-9a 4p-9p | AE1: Oct 9p-4a | AF1: Nov 9a-4p | AG1: Nov 4a-9a 4p-9p | AH1: Nov 9p-4a | AI1: Dec 9a-4p | AJ1: Dec 4a-9a 4p-9p | AK1: Dec 9p-4a
A2: Angelfish | B2: {=N('River (Adjusted)'!B2:AK32) * N('River (Adjusted)'!AN2:AN32)} -> 0 | C2: 0 | D2: 0 | E2: 0 | F2: 0 | G2: 0 | H2: 0 | I2: 0 | J2: 0 | K2: 0 | L2: 0 | M2: 0 | N2: 0 | O2: 176.47059 | P2: 183.67347 | Q2: 0 | R2: 183.67347 | S2: 180 | T2: 0 | U2: 109.09091 | V2: 107.14286 | W2: 0 | X2: 98.360656 | Y2: 96.774194 | Z2: 0 | AA2: 122.44898 | AB2: 122.44898 | AC2: 0 | AD2: 220.58824 | AE2: 220.58824 | AF2: 0 | AG2: 0 | AH2: 0 | AI2: 0 | AJ2: 0 | AK2: 0
A3: Arapaima | B3: 0 | C3: 0 | D3: 0 | E3: 0 | F3: 0 | G3: 0 | H3: 0 | I3: 0 | J3: 0 | K3: 0 | L3: 0 | M3: 0 | N3: 0 | O3: 0 | P3: 0 | Q3: 0 | R3: 204.08163 | S3: 200 | T3: 0 | U3: 181.81818 | V3: 178.57143 | W3: 0 | X3: 163.93443 | Y3: 161.29032 | Z3: 0 | AA3: 204.08163 | AB3: 204.08163 | AC3: 0 | AD3: 0 | AE3: 0 | AF3: 0 | AG3: 0 | AH3: 0 | AI3: 0 | AJ3: 0 | AK3: 0
A4: Arowana | B4: 0 | C4: 0 | D4: 0 | E4: 0 | F4: 0 | G4: 0 | H4: 0 | I4: 0 | J4: 0 | K4: 0 | L4: 0 | M4: 0 | N4: 0 | O4: 0 | P4: 0 | Q4: 0 | R4: 204.08163 | S4: 400 | T4: 0 | U4: 181.81818 | V4: 357.14286 | W4: 0 | X4: 163.93443 | Y4: 322.58065 | Z4: 0 | AA4: 204.08163 | AB4: 408.16327 | AC4: 0 | AD4: 0 | AE4: 0 | AF4: 0 | AG4: 0 | AH4: 0 | AI4: 0 | AJ4: 0 | AK4: 0
A5: Betta | B5: 0 | C5: 0 | D5: 0 | E5: 0 | F5: 0 | G5: 0 | H5: 0 | I5: 0 | J5: 0 | K5: 0 | L5: 0 | M5: 0 | N5: 79.365079 | O5: 0 | P5: 0 | Q5: 40.983607 | R5: 0 | S5: 0 | T5: 39.0625 | U5: 0 | V5: 0 | W5: 37.313433 | X5: 0 | Y5: 0 | Z5: 86.206897 | AA5: 0 | AB5: 0 | AC5: 136.9863 | AD5: 0 | AE5: 0 | AF5: 0 | AG5: 0 | AH5: 0 | AI5: 0 | AJ5: 0 | AK5: 0
A6: Bitterling | B6: 158.82353 | C6: 164.63415 | D6: 164.63415 | E6: 158.82353 | F6: 164.63415 | G6: 164.63415 | H6: 155.55556 | I6: 154.28571 | J6: 154.28571 | K6: 0 | L6: 0 | M6: 0 | N6: 0 | O6: 0 | P6: 0 | Q6: 0 | R6: 0 | S6: 0 | T6: 0 | U6: 0 | V6: 0 | W6: 0 | X6: 0 | Y6: 0 | Z6: 0 | AA6: 0 | AB6: 0 | AC6: 0 | AD6: 0 | AE6: 0 | AF6: 198.7013 | AG6: 194.59459 | AH6: 194.59459 | AI6: 136.04651 | AJ6: 137.64706 | AK6: 137.64706
A7: Black Bass | B7: 51.764706 | C7: 53.658537 | D7: 53.658537 | E7: 51.764706 | F7: 53.658537 | G7: 53.658537 | H7: 54.320988 | I7: 57.142857 | J7: 57.142857 | K7: 54.545455 | L7: 65.454545 | M7: 64.285714 | N7: 63.492063 | O7: 70.588235 | P7: 65.306122 | Q7: 65.57377 | R7: 81.632653 | S7: 72 | T7: 50 | U7: 58.181818 | V7: 50 | W7: 53.731343 | X7: 52.459016 | Y7: 51.612903 | Z7: 34.482759 | AA7: 32.653061 | AB7: 32.653061 | AC7: 49.315068 | AD7: 64.705882 | AE7: 58.823529 | AF7: 46.753247 | AG7: 54.054054 | AH7: 59.459459 | AI7: 55.813953 | AJ7: 56.470588 | AK7: 56.470588
A8: Blueguill | B8: 16.941176 | C8: 0 | D8: 0 | E8: 16.941176 | F8: 0 | G8: 0 | H8: 20 | I8: 0 | J8: 0 | K8: 24.545455 | L8: 0 | M8: 0 | N8: 22.857143 | O8: 0 | P8: 0 | Q8: 23.606557 | R8: 0 | S8: 0 | T8: 19.6875 | U8: 0 | V8: 0 | W8: 18.80597 | X8: 0 | Y8: 0 | Z8: 18.62069 | AA8: 0 | AB8: 0 | AC8: 19.726027 | AD8: 0 | AE8: 0 | AF8: 23.376623 | AG8: 0 | AH8: 0 | AI8: 14.651163 | AJ8: 0 | AK8: 0
A9: Crucian Carp | B9: 22.588235 | C9: 23.414634 | D9: 23.414634 | E9: 22.588235 | F9: 23.414634 | G9: 23.414634 | H9: 21.728395 | I9: 22.857143 | J9: 22.857143 | K9: 26.666667 | L9: 32 | M9: 28.571429 | N9: 22.857143 | O9: 28.235294 | P9: 22.857143 | Q9: 26.229508 | R9: 29.387755 | S9: 25.6 | T9: 22.5 | U9: 26.181818 | V9: 22.857143 | W9: 21.492537 | X9: 23.606557 | Y9: 20.645161 | Z9: 11.034483 | AA9: 13.061224 | AB9: 13.061224 | AC9: 19.726027 | AD9: 21.176471 | AE9: 18.823529 | AF9: 22.857143 | AG9: 25.945946 | AH9: 25.945946 | AI9: 20.465116 | AJ9: 22.588235 | AK9: 22.588235
A10: Dace | B10: 0 | C10: 23.414634 | D10: 23.414634 | E10: 0 | F10: 23.414634 | G10: 23.414634 | H10: 0 | I10: 30.857143 | J10: 30.857143 | K10: 0 | L10: 43.636364 | M10: 42.857143 | N10: 0 | O10: 42.352941 | P10: 39.183673 | Q10: 0 | R10: 34.285714 | S10: 33.6 | T10: 0 | U10: 30.545455 | V10: 30 | W10: 0 | X10: 31.47541 | Y10: 30.967742 | Z10: 0 | AA10: 14.693878 | AB10: 14.693878 | AC10: 0 | AD10: 28.235294 | AE10: 28.235294 | AF10: 0 | AG10: 32.432432 | AH10: 32.432432 | AI10: 0 | AJ10: 25.411765 | AK10: 25.411765
A11: Dorado | B11: 0 | C11: 0 | D11: 0 | E11: 0 | F11: 0 | G11: 0 | H11: 0 | I11: 0 | J11: 0 | K11: 0 | L11: 0 | M11: 0 | N11: 0 | O11: 0 | P11: 0 | Q11: 245.90164 | R11: 612.2449 | S11: 0 | T11: 234.375 | U11: 545.45455 | V11: 0 | W11: 223.8806 | X11: 491.80328 | Y11: 0 | Z11: 517.24138 | AA11: 612.2449 | AB11: 0 | AC11: 0 | AD11: 0 | AE11: 0 | AF11: 0 | AG11: 0 | AH11: 0 | AI11: 0 | AJ11: 0 | AK11: 0
A12: Freshwater Goby | B12: 0 | C12: 19.512195 | D12: 19.512195 | E12: 0 | F12: 19.512195 | G12: 19.512195 | H12: 0 | I12: 17.142857 | J12: 17.142857 | K12: 0 | L12: 21.818182 | M12: 21.428571 | N12: 0 | O12: 23.529412 | P12: 24.489796 | Q12: 0 | R12: 24.489796 | S12: 24 | T12: 0 | U12: 21.818182 | V12: 21.428571 | W12: 0 | X12: 19.672131 | Y12: 19.354839 | Z12: 0 | AA12: 24.489796 | AB12: 16.326531 | AC12: 0 | AD12: 29.411765 | AE12: 29.411765 | AF12: 0 | AG12: 16.216216 | AH12: 16.216216 | AI12: 0 | AJ12: 18.823529 | AK12: 18.823529
A13: Guppy | B13: 0 | C13: 0 | D13: 0 | E13: 0 | F13: 0 | G13: 0 | H13: 0 | I13: 0 | J13: 0 | K13: 59.090909 | L13: 0 | M13: 0 | N13: 41.269841 | O13: 0 | P13: 0 | Q13: 42.622951 | R13: 0 | S13: 0 | T13: 40.625 | U13: 0 | V13: 0 | W13: 38.80597 | X13: 0 | Y13: 0 | Z13: 44.827586 | AA13: 0 | AB13: 0 | AC13: 53.424658 | AD13: 0 | AE13: 0 | AF13: 50.649351 | AG13: 0 | AH13: 0 | AI13: 0 | AJ13: 0 | AK13: 0
A14: Loach | B14: 0 | C14: 0 | D14: 0 | E14: 0 | F14: 0 | G14: 0 | H14: 69.135802 | I14: 74.285714 | J14: 74.285714 | K14: 96.969697 | L14: 116.36364 | M14: 114.28571 | N14: 76.190476 | O14: 94.117647 | P14: 97.959184 | Q14: 0 | R14: 0 | S14: 0 | T14: 0 | U14: 0 | V14: 0 | W14: 0 | X14: 0 | Y14: 0 | Z14: 0 | AA14: 0 | AB14: 0 | AC14: 0 | AD14: 0 | AE14: 0 | AF14: 0 | AG14: 0 | AH14: 0 | AI14: 0 | AJ14: 0 | AK14: 0
... A32: Stone | B32: 0.23529412 | C32: 0.24390244 | D32: 0.24390244 | E32: 0.23529412 | F32: 0.24390244 | G32: 0.24390244 | H32: 0.24691358 | I32: 0.28571429 | J32: 0.28571429 | K32: 0.3030303 | L32: 0.36363636 | M32: 0.35714286 | N32: 0.31746032 | O32: 0.39215686 | P32: 0.40816327 | Q32: 0.32786885 | R32: 0.40816327 | S32: 0.4 | T32: 0.3125 | U32: 0.36363636 | V32: 0.35714286 | W32: 0.29850746 | X32: 0.32786885 | Y32: 0.32258065 | Z32: 0.34482759 | AA32: 0.40816327 | AB32: 0.40816327 | AC32: 0.2739726 | AD32: 0.29411765 | AE32: 0.29411765 | AF32: 0.25974026 | AG32: 0.27027027 | AH32: 0.27027027 | AI32: 0.23255814 | AJ32: 0.23529412 | AK32: 0.23529412
A33: Expected Profit Per Catch | B33: =SUM(B2:B32) -> 380.23529 | C33: =SUM(C2:C32) -> 402.43902 | D33: =SUM(D2:D32) -> 402.43902 | E33: =SUM(E2:E32) -> 380.23529 | F33: =SUM(F2:F32) -> 402.43902 | G33: =SUM(G2:G32) -> 402.43902 | H33: =SUM(H2:H32) -> 369.62963 | I33: =SUM(I2:I32) -> 387.42857 | ... AK33: =SUM(AK2:AK32) -> 405.17647

Sheet Cliff Top (Original Data)
B1: Jan 9a-4p | C1: Jan 4a-9a 4p-9p | D1: Jan 9p-4a | E1: Feb 9a-4p | F1: Feb 4a-9a 4p-9p | G1: Feb 9p-4a | H1: Mar 9a-4p | I1: Mar 4a-9a 4p-9p | J1: Mar 9p-4a | K1: Apr 9a-4p | L1: Apr 4a-9a 4p-9p | M1: Apr 9p-4a | N1: May 9a-4p | O1: May 4a-9a 4p-9p | P1: May 9p-4a | Q1: Jun 9a-4p | R1: Jun 4a-9a 4p-9p | S1: Jun 9p-4a | T1: Jul 9a-4p | U1: Jul 4a-9a 4p-9p | V1: Jul 9p-4a | W1: Aug 9a-4p | X1: Aug 4a-9a 4p-9p | Y1: Aug 9p-4a | Z1: Sep 9a-4p | AA1: Sep 4a-9a 4p-9p | AB1: Sep 9p-4a | AC1: Oct 9a-4p | AD1: Oct 4a-9a 4p-9p | AE1: Oct 9p-4a | AF1: Nov 9a-4p | AG1: Nov 4a-9a 4p-9p | AH1: Nov 9p-4a | AI1: Dec 9a-4p | AJ1: Dec 4a-9a 4p-9p | AK1: Dec 9p-4a
A2: Char | B2: 0 | C2: 0 | D2: 0 | E2: 0 | F2: 0 | G2: 0 | H2: 0 | I2: 1 | J2: 1 | K2: 0 | L2: 1 | M2: 1 | N2: 0 | O2: 1 | P2: 1 | Q2: 0 | R2: 1 | S2: 1 | T2: 0 | U2: 0 | V2: 0 | W2: 0 | X2: 0 | Y2: 0 | Z2: 2 | AA2: 1 | AB2: 1 | AC2: 4 | AD2: 1 | AE2: 1 | AF2: 2 | AG2: 1 | AH2: 1 | AI2: 0 | AJ2: 0 | AK2: 0
A3: Cherry Salmon | B3: 0 | C3: 0 | D3: 0 | E3: 0 | F3: 0 | G3: 0 | H3: 0 | I3: 7 | J3: 7 | K3: 0 | L3: 8 | M3: 8 | N3: 0 | O3: 6 | P3: 6 | Q3: 0 | R3: 7 | S3: 7 | T3: 0 | U3: 0 | V3: 0 | W3: 0 | X3: 0 | Y3: 0 | Z3: 3 | AA3: 6 | AB3: 6 | AC3: 8 | AD3: 8 | AE3: 8 | AF3: 3 | AG3: 9 | AH3: 9 | AI3: 0 | AJ3: 0 | AK3: 0
A4: Golden Trout | B4: 0 | C4: 0 | D4: 0 | E4: 0 | F4: 0 | G4: 0 | H4: 0 | I4: 1 | J4: 1 | K4: 0 | L4: 1 | M4: 1 | N4: 0 | O4: 1 | P4: 1 | Q4: 0 | R4: 0 | S4: 0 | T4: 0 | U4: 0 | V4: 0 | W4: 0 | X4: 0 | Y4: 0 | Z4: 0 | AA4: 1 | AB4: 1 | AC4: 0 | AD4: 1 | AE4: 1 | AF4: 0 | AG4: 1 | AH4: 1 | AI4: 0 | AJ4: 0 | AK4: 0
A5: Stringfish | B5: 0 | C5: 1 | D5: 1 | E5: 0 | F5: 1 | G5: 1 | H5: 0 | I5: 1 | J5: 1 | K5: 0 | L5: 0 | M5: 0 | N5: 0 | O5: 0 | P5: 0 | Q5: 0 | R5: 0 | S5: 0 | T5: 0 | U5: 0 | V5: 0 | W5: 0 | X5: 0 | Y5: 0 | Z5: 0 | AA5: 0 | AB5: 0 | AC5: 0 | AD5: 0 | AE5: 0 | AF5: 0 | AG5: 0 | AH5: 0 | AI5: 0 | AJ5: 1 | AK5: 1
A6: Can | B6: 2 | C6: 2 | D6: 2 | E6: 2 | F6: 2 | G6: 2 | H6: 2 | I6: 2 | J6: 2 | K6: 2 | L6: 2 | M6: 2 | N6: 2 | O6: 2 | P6: 2 | Q6: 2 | R6: 2 | S6: 2 | T6: 2 | U6: 2 | V6: 2 | W6: 2 | X6: 2 | Y6: 2 | Z6: 2 | AA6: 2 | AB6: 2 | AC6: 2 | AD6: 2 | AE6: 2 | AF6: 2 | AG6: 2 | AH6: 2 | AI6: 2 | AJ6: 2 | AK6: 2
A7: Boot | B7: 1 | C7: 1 | D7: 1 | E7: 1 | F7: 1 | G7: 1 | H7: 1 | I7: 1 | J7: 1 | K7: 1 | L7: 1 | M7: 1 | N7: 1 | O7: 1 | P7: 1 | Q7: 1 | R7: 1 | S7: 1 | T7: 1 | U7: 1 | V7: 1 | W7: 1 | X7: 1 | Y7: 1 | Z7: 1 | AA7: 1 | AB7: 1 | AC7: 1 | AD7: 1 | AE7: 1 | AF7: 1 | AG7: 1 | AH7: 1 | AI7: 1 | AJ7: 1 | AK7: 1
A8: Tire | B8: 1 | C8: 1 | D8: 1 | E8: 1 | F8: 1 | G8: 1 | H8: 1 | I8: 1 | J8: 1 | K8: 1 | L8: 1 | M8: 1 | N8: 1 | O8: 1 | P8: 1 | Q8: 1 | R8: 1 | S8: 1 | T8: 1 | U8: 1 | V8: 1 | W8: 1 | X8: 1 | Y8: 1 | Z8: 1 | AA8: 1 | AB8: 1 | AC8: 1 | AD8: 1 | AE8: 1 | AF8: 1 | AG8: 1 | AH8: 1 | AI8: 1 | AJ8: 1 | AK8: 1
A9: Stone | B9: 2 | C9: 2 | D9: 2 | E9: 2 | F9: 2 | G9: 2 | H9: 2 | I9: 2 | J9: 2 | K9: 2 | L9: 2 | M9: 2 | N9: 2 | O9: 2 | P9: 2 | Q9: 2 | R9: 2 | S9: 2 | T9: 2 | U9: 2 | V9: 2 | W9: 2 | X9: 2 | Y9: 2 | Z9: 2 | AA9: 2 | AB9: 2 | AC9: 2 | AD9: 2 | AE9: 2 | AF9: 2 | AG9: 2 | AH9: 2 | AI9: 2 | AJ9: 2 | AK9: 2

Sheet Cliff Top (Adjusted)
B1: Jan 9a-4p | C1: Jan 4a-9a 4p-9p | D1: Jan 9p-4a | E1: Feb 9a-4p | F1: Feb 4a-9a 4p-9p | G1: Feb 9p-4a | H1: Mar 9a-4p | I1: Mar 4a-9a 4p-9p | J1: Mar 9p-4a | K1: Apr 9a-4p | L1: Apr 4a-9a 4p-9p | M1: Apr 9p-4a | N1: May 9a-4p | O1: May 4a-9a 4p-9p | P1: May 9p-4a | Q1: Jun 9a-4p | R1: Jun 4a-9a 4p-9p | S1: Jun 9p-4a | T1: Jul 9a-4p | U1: Jul 4a-9a 4p-9p | V1: Jul 9p-4a | W1: Aug 9a-4p | X1: Aug 4a-9a 4p-9p | Y1: Aug 9p-4a | Z1: Sep 9a-4p | AA1: Sep 4a-9a 4p-9p | AB1: Sep 9p-4a | AC1: Oct 9a-4p | AD1: Oct 4a-9a 4p-9p | AE1: Oct 9p-4a | AF1: Nov 9a-4p | AG1: Nov 4a-9a 4p-9p | AH1: Nov 9p-4a | AI1: Dec 9a-4p | AJ1: Dec 4a-9a 4p-9p | AK1: Dec 9p-4a | AN1: Prices
A2: Char | B2: {=IF( 'Cliff Top (Original Data)'!B2:AK32 = "", "", 'Cliff Top (Original Data)'!B2:AK32 / (MMULT(TRANSPOSE(SIGN(ROW('Cliff Top (Original Data)'!B2:AK32))), N('Cliff Top (Original Data)'!B2:AK32))) )} -> 0 | C2: 0 | D2: 0 | E2: 0 | F2: 0 | G2: 0 | H2: 0 | I2: 0.0625 | J2: 0.0625 | K2: 0 | L2: 0.0625 | M2: 0.0625 | N2: 0 | O2: 0.071428571 | P2: 0.071428571 | Q2: 0 | R2: 0.071428571 | S2: 0.071428571 | T2: 0 | U2: 0 | V2: 0 | W2: 0 | X2: 0 | Y2: 0 | Z2: 0.18181818 | AA2: 0.071428571 | AB2: 0.071428571 | AC2: 0.22222222 | AD2: 0.0625 | AE2: 0.0625 | AF2: 0.18181818 | AG2: 0.058823529 | AH2: 0.058823529 | AI2: 0 | AJ2: 0 | AK2: 0 | AM2: Char | AN2: 3800
A3: Cherry Salmon | B3: 0 | C3: 0 | D3: 0 | E3: 0 | F3: 0 | G3: 0 | H3: 0 | I3: 0.4375 | J3: 0.4375 | K3: 0 | L3: 0.5 | M3: 0.5 | N3: 0 | O3: 0.42857143 | P3: 0.42857143 | Q3: 0 | R3: 0.5 | S3: 0.5 | T3: 0 | U3: 0 | V3: 0 | W3: 0 | X3: 0 | Y3: 0 | Z3: 0.27272727 | AA3: 0.42857143 | AB3: 0.42857143 | AC3: 0.44444444 | AD3: 0.5 | AE3: 0.5 | AF3: 0.27272727 | AG3: 0.52941176 | AH3: 0.52941176 | AI3: 0 | AJ3: 0 | AK3: 0 | AM3: Cherry Salmon | AN3: 1000
A4: Golden Trout | B4: 0 | C4: 0 | D4: 0 | E4: 0 | F4: 0 | G4: 0 | H4: 0 | I4: 0.0625 | J4: 0.0625 | K4: 0 | L4: 0.0625 | M4: 0.0625 | N4: 0 | O4: 0.071428571 | P4: 0.071428571 | Q4: 0 | R4: 0 | S4: 0 | T4: 0 | U4: 0 | V4: 0 | W4: 0 | X4: 0 | Y4: 0 | Z4: 0 | AA4: 0.071428571 | AB4: 0.071428571 | AC4: 0 | AD4: 0.0625 | AE4: 0.0625 | AF4: 0 | AG4: 0.058823529 | AH4: 0.058823529 | AI4: 0 | AJ4: 0 | AK4: 0 | AM4: Golden Trout | AN4: 15000
A5: Stringfish | B5: 0 | C5: 0.14285714 | D5: 0.14285714 | E5: 0 | F5: 0.14285714 | G5: 0.14285714 | H5: 0 | I5: 0.0625 | J5: 0.0625 | K5: 0 | L5: 0 | M5: 0 | N5: 0 | O5: 0 | P5: 0 | Q5: 0 | R5: 0 | S5: 0 | T5: 0 | U5: 0 | V5: 0 | W5: 0 | X5: 0 | Y5: 0 | Z5: 0 | AA5: 0 | AB5: 0 | AC5: 0 | AD5: 0 | AE5: 0 | AF5: 0 | AG5: 0 | AH5: 0 | AI5: 0 | AJ5: 0.14285714 | AK5: 0.14285714 | AM5: Stringfish | AN5: 15000
A6: Can | B6: 0.33333333 | C6: 0.28571429 | D6: 0.28571429 | E6: 0.33333333 | F6: 0.28571429 | G6: 0.28571429 | H6: 0.33333333 | I6: 0.125 | J6: 0.125 | K6: 0.33333333 | L6: 0.125 | M6: 0.125 | N6: 0.33333333 | O6: 0.14285714 | P6: 0.14285714 | Q6: 0.33333333 | R6: 0.14285714 | S6: 0.14285714 | T6: 0.33333333 | U6: 0.33333333 | V6: 0.33333333 | W6: 0.33333333 | X6: 0.33333333 | Y6: 0.33333333 | Z6: 0.18181818 | AA6: 0.14285714 | AB6: 0.14285714 | AC6: 0.11111111 | AD6: 0.125 | AE6: 0.125 | AF6: 0.18181818 | AG6: 0.11764706 | AH6: 0.11764706 | AI6: 0.33333333 | AJ6: 0.28571429 | AK6: 0.28571429 | AM6: Can | AN6: 10
A7: Boot | B7: 0.16666667 | C7: 0.14285714 | D7: 0.14285714 | E7: 0.16666667 | F7: 0.14285714 | G7: 0.14285714 | H7: 0.16666667 | I7: 0.0625 | J7: 0.0625 | K7: 0.16666667 | L7: 0.0625 | M7: 0.0625 | N7: 0.16666667 | O7: 0.071428571 | P7: 0.071428571 | Q7: 0.16666667 | R7: 0.071428571 | S7: 0.071428571 | T7: 0.16666667 | U7: 0.16666667 | V7: 0.16666667 | W7: 0.16666667 | X7: 0.16666667 | Y7: 0.16666667 | Z7: 0.090909091 | AA7: 0.071428571 | AB7: 0.071428571 | AC7: 0.055555556 | AD7: 0.0625 | AE7: 0.0625 | AF7: 0.090909091 | AG7: 0.058823529 | AH7: 0.058823529 | AI7: 0.16666667 | AJ7: 0.14285714 | AK7: 0.14285714 | AM7: Boot | AN7: 10
A8: Tire | B8: 0.16666667 | C8: 0.14285714 | D8: 0.14285714 | E8: 0.16666667 | F8: 0.14285714 | G8: 0.14285714 | H8: 0.16666667 | I8: 0.0625 | J8: 0.0625 | K8: 0.16666667 | L8: 0.0625 | M8: 0.0625 | N8: 0.16666667 | O8: 0.071428571 | P8: 0.071428571 | Q8: 0.16666667 | R8: 0.071428571 | S8: 0.071428571 | T8: 0.16666667 | U8: 0.16666667 | V8: 0.16666667 | W8: 0.16666667 | X8: 0.16666667 | Y8: 0.16666667 | Z8: 0.090909091 | AA8: 0.071428571 | AB8: 0.071428571 | AC8: 0.055555556 | AD8: 0.0625 | AE8: 0.0625 | AF8: 0.090909091 | AG8: 0.058823529 | AH8: 0.058823529 | AI8: 0.16666667 | AJ8: 0.14285714 | AK8: 0.14285714 | AM8: Tire | AN8: 10
A9: Stone | B9: 0.33333333 | C9: 0.28571429 | D9: 0.28571429 | E9: 0.33333333 | F9: 0.28571429 | G9: 0.28571429 | H9: 0.33333333 | I9: 0.125 | J9: 0.125 | K9: 0.33333333 | L9: 0.125 | M9: 0.125 | N9: 0.33333333 | O9: 0.14285714 | P9: 0.14285714 | Q9: 0.33333333 | R9: 0.14285714 | S9: 0.14285714 | T9: 0.33333333 | U9: 0.33333333 | V9: 0.33333333 | W9: 0.33333333 | X9: 0.33333333 | Y9: 0.33333333 | Z9: 0.18181818 | AA9: 0.14285714 | AB9: 0.14285714 | AC9: 0.11111111 | AD9: 0.125 | AE9: 0.125 | AF9: 0.18181818 | AG9: 0.11764706 | AH9: 0.11764706 | AI9: 0.33333333 | AJ9: 0.28571429 | AK9: 0.28571429 | AM9: Stone | AN9: 10

Sheet Cliff Top (Expected Prices)
B1: Jan 9a-4p | C1: Jan 4a-9a 4p-9p | D1: Jan 9p-4a | E1: Feb 9a-4p | F1: Feb 4a-9a 4p-9p | G1: Feb 9p-4a | H1: Mar 9a-4p | I1: Mar 4a-9a 4p-9p | J1: Mar 9p-4a | K1: Apr 9a-4p | L1: Apr 4a-9a 4p-9p | M1: Apr 9p-4a | N1: May 9a-4p | O1: May 4a-9a 4p-9p | P1: May 9p-4a | Q1: Jun 9a-4p | R1: Jun 4a-9a 4p-9p | S1: Jun 9p-4a | T1: Jul 9a-4p | U1: Jul 4a-9a 4p-9p | V1: Jul 9p-4a | W1: Aug 9a-4p | X1: Aug 4a-9a 4p-9p | Y1: Aug 9p-4a | Z1: Sep 9a-4p | AA1: Sep 4a-9a 4p-9p | AB1: Sep 9p-4a | AC1: Oct 9a-4p | AD1: Oct 4a-9a 4p-9p | AE1: Oct 9p-4a | AF1: Nov 9a-4p | AG1: Nov 4a-9a 4p-9p | AH1: Nov 9p-4a | AI1: Dec 9a-4p | AJ1: Dec 4a-9a 4p-9p | AK1: Dec 9p-4a
A2: Char | B2: {=N('Cliff Top (Adjusted)'!B2:AK9) * N('Cliff Top (Adjusted)'!AN2:AN9)} -> 0 | C2: 0 | D2: 0 | E2: 0 | F2: 0 | G2: 0 | H2: 0 | I2: 237.5 | J2: 237.5 | K2: 0 | L2: 237.5 | M2: 237.5 | N2: 0 | O2: 271.42857 | P2: 271.42857 | Q2: 0 | R2: 271.42857 | S2: 271.42857 | T2: 0 | U2: 0 | V2: 0 | W2: 0 | X2: 0 | Y2: 0 | Z2: 690.90909 | AA2: 271.42857 | AB2: 271.42857 | AC2: 844.44444 | AD2: 237.5 | AE2: 237.5 | AF2: 690.90909 | AG2: 223.52941 | AH2: 223.52941 | AI2: 0 | AJ2: 0 | AK2: 0
A3: Cherry Salmon | B3: 0 | C3: 0 | D3: 0 | E3: 0 | F3: 0 | G3: 0 | H3: 0 | I3: 437.5 | J3: 437.5 | K3: 0 | L3: 500 | M3: 500 | N3: 0 | O3: 428.57143 | P3: 428.57143 | Q3: 0 | R3: 500 | S3: 500 | T3: 0 | U3: 0 | V3: 0 | W3: 0 | X3: 0 | Y3: 0 | Z3: 272.72727 | AA3: 428.57143 | AB3: 428.57143 | AC3: 444.44444 | AD3: 500 | AE3: 500 | AF3: 272.72727 | AG3: 529.41176 | AH3: 529.41176 | AI3: 0 | AJ3: 0 | AK3: 0
A4: Golden Trout | B4: 0 | C4: 0 | D4: 0 | E4: 0 | F4: 0 | G4: 0 | H4: 0 | I4: 937.5 | J4: 937.5 | K4: 0 | L4: 937.5 | M4: 937.5 | N4: 0 | O4: 1071.4286 | P4: 1071.4286 | Q4: 0 | R4: 0 | S4: 0 | T4: 0 | U4: 0 | V4: 0 | W4: 0 | X4: 0 | Y4: 0 | Z4: 0 | AA4: 1071.4286 | AB4: 1071.4286 | AC4: 0 | AD4: 937.5 | AE4: 937.5 | AF4: 0 | AG4: 882.35294 | AH4: 882.35294 | AI4: 0 | AJ4: 0 | AK4: 0
A5: Stringfish | B5: 0 | C5: 2142.8571 | D5: 2142.8571 | E5: 0 | F5: 2142.8571 | G5: 2142.8571 | H5: 0 | I5: 937.5 | J5: 937.5 | K5: 0 | L5: 0 | M5: 0 | N5: 0 | O5: 0 | P5: 0 | Q5: 0 | R5: 0 | S5: 0 | T5: 0 | U5: 0 | V5: 0 | W5: 0 | X5: 0 | Y5: 0 | Z5: 0 | AA5: 0 | AB5: 0 | AC5: 0 | AD5: 0 | AE5: 0 | AF5: 0 | AG5: 0 | AH5: 0 | AI5: 0 | AJ5: 2142.8571 | AK5: 2142.8571
A6: Can | B6: 3.3333333 | C6: 2.8571429 | D6: 2.8571429 | E6: 3.3333333 | F6: 2.8571429 | G6: 2.8571429 | H6: 3.3333333 | I6: 1.25 | J6: 1.25 | K6: 3.3333333 | L6: 1.25 | M6: 1.25 | N6: 3.3333333 | O6: 1.4285714 | P6: 1.4285714 | Q6: 3.3333333 | R6: 1.4285714 | S6: 1.4285714 | T6: 3.3333333 | U6: 3.3333333 | V6: 3.3333333 | W6: 3.3333333 | X6: 3.3333333 | Y6: 3.3333333 | Z6: 1.8181818 | AA6: 1.4285714 | AB6: 1.4285714 | AC6: 1.1111111 | AD6: 1.25 | AE6: 1.25 | AF6: 1.8181818 | AG6: 1.1764706 | AH6: 1.1764706 | AI6: 3.3333333 | AJ6: 2.8571429 | AK6: 2.8571429
A7: Boot | B7: 1.6666667 | C7: 1.4285714 | D7: 1.4285714 | E7: 1.6666667 | F7: 1.4285714 | G7: 1.4285714 | H7: 1.6666667 | I7: 0.625 | J7: 0.625 | K7: 1.6666667 | L7: 0.625 | M7: 0.625 | N7: 1.6666667 | O7: 0.71428571 | P7: 0.71428571 | Q7: 1.6666667 | R7: 0.71428571 | S7: 0.71428571 | T7: 1.6666667 | U7: 1.6666667 | V7: 1.6666667 | W7: 1.6666667 | X7: 1.6666667 | Y7: 1.6666667 | Z7: 0.90909091 | AA7: 0.71428571 | AB7: 0.71428571 | AC7: 0.55555556 | AD7: 0.625 | AE7: 0.625 | AF7: 0.90909091 | AG7: 0.58823529 | AH7: 0.58823529 | AI7: 1.6666667 | AJ7: 1.4285714 | AK7: 1.4285714
A8: Tire | B8: 1.6666667 | C8: 1.4285714 | D8: 1.4285714 | E8: 1.6666667 | F8: 1.4285714 | G8: 1.4285714 | H8: 1.6666667 | I8: 0.625 | J8: 0.625 | K8: 1.6666667 | L8: 0.625 | M8: 0.625 | N8: 1.6666667 | O8: 0.71428571 | P8: 0.71428571 | Q8: 1.6666667 | R8: 0.71428571 | S8: 0.71428571 | T8: 1.6666667 | U8: 1.6666667 | V8: 1.6666667 | W8: 1.6666667 | X8: 1.6666667 | Y8: 1.6666667 | Z8: 0.90909091 | AA8: 0.71428571 | AB8: 0.71428571 | AC8: 0.55555556 | AD8: 0.625 | AE8: 0.625 | AF8: 0.90909091 | AG8: 0.58823529 | AH8: 0.58823529 | AI8: 1.6666667 | AJ8: 1.4285714 | AK8: 1.4285714
A9: Stone | B9: 3.3333333 | C9: 2.8571429 | D9: 2.8571429 | E9: 3.3333333 | F9: 2.8571429 | G9: 2.8571429 | H9: 3.3333333 | I9: 1.25 | J9: 1.25 | K9: 3.3333333 | L9: 1.25 | M9: 1.25 | N9: 3.3333333 | O9: 1.4285714 | P9: 1.4285714 | Q9: 3.3333333 | R9: 1.4285714 | S9: 1.4285714 | T9: 3.3333333 | U9: 3.3333333 | V9: 3.3333333 | W9: 3.3333333 | X9: 3.3333333 | Y9: 3.3333333 | Z9: 1.8181818 | AA9: 1.4285714 | AB9: 1.4285714 | AC9: 1.1111111 | AD9: 1.25 | AE9: 1.25 | AF9: 1.8181818 | AG9: 1.1764706 | AH9: 1.1764706 | AI9: 3.3333333 | AJ9: 2.8571429 | AK9: 2.8571429
A10: Expected Profit Per Catch | B10: =SUM(B2:B9) -> 10 | C10: =SUM(C2:C9) -> 2151.4286 | D10: =SUM(D2:D9) -> 2151.4286 | E10: =SUM(E2:E9) -> 10 | F10: =SUM(F2:F9) -> 2151.4286 | G10: =SUM(G2:G9) -> 2151.4286 | H10: =SUM(H2:H9) -> 10 | I10: =SUM(I2:I9) -> 2553.75 | ... AK10: =SUM(AK2:AK9) -> 2151.4286

Sheet Mouth of River (Original Data)
B1: Jan 9a-4p | C1: Jan 4a-9a 4p-9p | D1: Jan 9p-4a | E1: Feb 9a-4p | F1: Feb 4a-9a 4p-9p | G1: Feb 9p-4a | H1: Mar 9a-4p | I1: Mar 4a-9a 4p-9p | J1: Mar 9p-4a | K1: Apr 9a-4p | L1: Apr 4a-9a 4p-9p | M1: Apr 9p-4a | N1: May 9a-4p | O1: May 4a-9a 4p-9p | P1: May 9p-4a | Q1: Jun 9a-4p | R1: Jun 4a-9a 4p-9p | S1: Jun 9p-4a | T1: Jul 9a-4p | U1: Jul 4a-9a 4p-9p | V1: Jul 9p-4a | W1: Aug 9a-4p | X1: Aug 4a-9a 4p-9p | Y1: Aug 9p-4a | Z1: Sep 9a-4p | AA1: Sep 4a-9a 4p-9p | AB1: Sep 9p-4a | AC1: Oct 9a-4p | AD1: Oct 4a-9a 4p-9p | AE1: Oct 9p-4a | AF1: Nov 9a-4p | AG1: Nov 4a-9a 4p-9p | AH1: Nov 9p-4a | AI1: Dec 9a-4p | AJ1: Dec 4a-9a 4p-9p | AK1: Dec 9p-4a
A2: Kingsalmon | B2: 0 | C2: 0 | D2: 0 | E2: 0 | F2: 0 | G2: 0 | H2: 0 | I2: 0 | J2: 0 | K2: 0 | L2: 0 | M2: 0 | N2: 0 | O2: 0 | P2: 0 | Q2: 0 | R2: 0 | S2: 0 | T2: 0 | U2: 0 | V2: 0 | W2: 0 | X2: 0 | Y2: 0 | Z2: 5 | AA2: 5 | AB2: 5 | AC2: 0 | AD2: 0 | AE2: 0 | AF2: 0 | AG2: 0 | AH2: 0 | AI2: 0 | AJ2: 0 | AK2: 0
A3: Salmon | B3: 0 | C3: 0 | D3: 0 | E3: 0 | F3: 0 | G3: 0 | H3: 0 | I3: 0 | J3: 0 | K3: 0 | L3: 0 | M3: 0 | N3: 0 | O3: 0 | P3: 0 | Q3: 0 | R3: 0 | S3: 0 | T3: 0 | U3: 0 | V3: 0 | W3: 0 | X3: 0 | Y3: 0 | Z3: 20 | AA3: 20 | AB3: 20 | AC3: 0 | AD3: 0 | AE3: 0 | AF3: 0 | AG3: 0 | AH3: 0 | AI3: 0 | AJ3: 0 | AK3: 0
A4: Sturgeon | B4: 2 | C4: 2 | D4: 2 | E4: 2 | F4: 2 | G4: 2 | H4: 1 | I4: 1 | J4: 1 | K4: 0 | L4: 0 | M4: 0 | N4: 0 | O4: 0 | P4: 0 | Q4: 0 | R4: 0 | S4: 0 | T4: 0 | U4: 0 | V4: 0 | W4: 0 | X4: 0 | Y4: 0 | Z4: 1 | AA4: 1 | AB4: 1 | AC4: 1 | AD4: 1 | AE4: 1 | AF4: 4 | AG4: 4 | AH4: 4 | AI4: 1 | AJ4: 1 | AK4: 1
A5: Can | B5: 2 | C5: 2 | D5: 2 | E5: 2 | F5: 2 | G5: 2 | H5: 2 | I5: 2 | J5: 2 | K5: 2 | L5: 2 | M5: 2 | N5: 2 | O5: 2 | P5: 2 | Q5: 2 | R5: 2 | S5: 2 | T5: 2 | U5: 2 | V5: 2 | W5: 2 | X5: 2 | Y5: 2 | Z5: 2 | AA5: 2 | AB5: 2 | AC5: 2 | AD5: 2 | AE5: 2 | AF5: 2 | AG5: 2 | AH5: 2 | AI5: 2 | AJ5: 2 | AK5: 2
A6: Boot | B6: 1 | C6: 1 | D6: 1 | E6: 1 | F6: 1 | G6: 1 | H6: 1 | I6: 1 | J6: 1 | K6: 1 | L6: 1 | M6: 1 | N6: 1 | O6: 1 | P6: 1 | Q6: 1 | R6: 1 | S6: 1 | T6: 1 | U6: 1 | V6: 1 | W6: 1 | X6: 1 | Y6: 1 | Z6: 1 | AA6: 1 | AB6: 1 | AC6: 1 | AD6: 1 | AE6: 1 | AF6: 1 | AG6: 1 | AH6: 1 | AI6: 1 | AJ6: 1 | AK6: 1
A7: Tire | B7: 1 | C7: 1 | D7: 1 | E7: 1 | F7: 1 | G7: 1 | H7: 1 | I7: 1 | J7: 1 | K7: 1 | L7: 1 | M7: 1 | N7: 1 | O7: 1 | P7: 1 | Q7: 1 | R7: 1 | S7: 1 | T7: 1 | U7: 1 | V7: 1 | W7: 1 | X7: 1 | Y7: 1 | Z7: 1 | AA7: 1 | AB7: 1 | AC7: 1 | AD7: 1 | AE7: 1 | AF7: 1 | AG7: 1 | AH7: 1 | AI7: 1 | AJ7: 1 | AK7: 1
A8: Stone | B8: 2 | C8: 2 | D8: 2 | E8: 2 | F8: 2 | G8: 2 | H8: 2 | I8: 2 | J8: 2 | K8: 2 | L8: 2 | M8: 2 | N8: 2 | O8: 2 | P8: 2 | Q8: 2 | R8: 2 | S8: 2 | T8: 2 | U8: 2 | V8: 2 | W8: 2 | X8: 2 | Y8: 2 | Z8: 2 | AA8: 2 | AB8: 2 | AC8: 2 | AD8: 2 | AE8: 2 | AF8: 2 | AG8: 2 | AH8: 2 | AI8: 2 | AJ8: 2 | AK8: 2

Sheet Mouth of River (Adjusted)
B1: Jan 9a-4p | C1: Jan 4a-9a 4p-9p | D1: Jan 9p-4a | E1: Feb 9a-4p | F1: Feb 4a-9a 4p-9p | G1: Feb 9p-4a | H1: Mar 9a-4p | I1: Mar 4a-9a 4p-9p | J1: Mar 9p-4a | K1: Apr 9a-4p | L1: Apr 4a-9a 4p-9p | M1: Apr 9p-4a | N1: May 9a-4p | O1: May 4a-9a 4p-9p | P1: May 9p-4a | Q1: Jun 9a-4p | R1: Jun 4a-9a 4p-9p | S1: Jun 9p-4a | T1: Jul 9a-4p | U1: Jul 4a-9a 4p-9p | V1: Jul 9p-4a | W1: Aug 9a-4p | X1: Aug 4a-9a 4p-9p | Y1: Aug 9p-4a | Z1: Sep 9a-4p | AA1: Sep 4a-9a 4p-9p | AB1: Sep 9p-4a | AC1: Oct 9a-4p | AD1: Oct 4a-9a 4p-9p | AE1: Oct 9p-4a | AF1: Nov 9a-4p | AG1: Nov 4a-9a 4p-9p | AH1: Nov 9p-4a | AI1: Dec 9a-4p | AJ1: Dec 4a-9a 4p-9p | AK1: Dec 9p-4a | AN1: Sales Price
A2: Kingsalmon | B2: {=IF( 'Mouth of River (Original Data)'!B2:AK32 = "", "", 'Mouth of River (Original Data)'!B2:AK32 / (MMULT(TRANSPOSE(SIGN(ROW('Mouth of River (Original Data)'!B2:AK32))), N('Mouth of River (Original Data)'!B2:AK32))) )} -> 0 | C2: 0 | D2: 0 | E2: 0 | F2: 0 | G2: 0 | H2: 0 | I2: 0 | J2: 0 | K2: 0 | L2: 0 | M2: 0 | N2: 0 | O2: 0 | P2: 0 | Q2: 0 | R2: 0 | S2: 0 | T2: 0 | U2: 0 | V2: 0 | W2: 0 | X2: 0 | Y2: 0 | Z2: 0.15625 | AA2: 0.15625 | AB2: 0.15625 | AC2: 0 | AD2: 0 | AE2: 0 | AF2: 0 | AG2: 0 | AH2: 0 | AI2: 0 | AJ2: 0 | AK2: 0 | AM2: King Salmon | AN2: 1800
A3: Salmon | B3: 0 | C3: 0 | D3: 0 | E3: 0 | F3: 0 | G3: 0 | H3: 0 | I3: 0 | J3: 0 | K3: 0 | L3: 0 | M3: 0 | N3: 0 | O3: 0 | P3: 0 | Q3: 0 | R3: 0 | S3: 0 | T3: 0 | U3: 0 | V3: 0 | W3: 0 | X3: 0 | Y3: 0 | Z3: 0.625 | AA3: 0.625 | AB3: 0.625 | AC3: 0 | AD3: 0 | AE3: 0 | AF3: 0 | AG3: 0 | AH3: 0 | AI3: 0 | AJ3: 0 | AK3: 0 | AM3: Salmon | AN3: 700
A4: Sturgeon | B4: 0.25 | C4: 0.25 | D4: 0.25 | E4: 0.25 | F4: 0.25 | G4: 0.25 | H4: 0.14285714 | I4: 0.14285714 | J4: 0.14285714 | K4: 0 | L4: 0 | M4: 0 | N4: 0 | O4: 0 | P4: 0 | Q4: 0 | R4: 0 | S4: 0 | T4: 0 | U4: 0 | V4: 0 | W4: 0 | X4: 0 | Y4: 0 | Z4: 0.03125 | AA4: 0.03125 | AB4: 0.03125 | AC4: 0.14285714 | AD4: 0.14285714 | AE4: 0.14285714 | AF4: 0.4 | AG4: 0.4 | AH4: 0.4 | AI4: 0.14285714 | AJ4: 0.14285714 | AK4: 0.14285714 | AM4: Sturgeon | AN4: 10000
A5: Can | B5: 0.25 | C5: 0.25 | D5: 0.25 | E5: 0.25 | F5: 0.25 | G5: 0.25 | H5: 0.28571429 | I5: 0.28571429 | J5: 0.28571429 | K5: 0.33333333 | L5: 0.33333333 | M5: 0.33333333 | N5: 0.33333333 | O5: 0.33333333 | P5: 0.33333333 | Q5: 0.33333333 | R5: 0.33333333 | S5: 0.33333333 | T5: 0.33333333 | U5: 0.33333333 | V5: 0.33333333 | W5: 0.33333333 | X5: 0.33333333 | Y5: 0.33333333 | Z5: 0.0625 | AA5: 0.0625 | AB5: 0.0625 | AC5: 0.28571429 | AD5: 0.28571429 | AE5: 0.28571429 | AF5: 0.2 | AG5: 0.2 | AH5: 0.2 | AI5: 0.28571429 | AJ5: 0.28571429 | AK5: 0.28571429 | AM5: Can | AN5: 10
A6: Boot | B6: 0.125 | C6: 0.125 | D6: 0.125 | E6: 0.125 | F6: 0.125 | G6: 0.125 | H6: 0.14285714 | I6: 0.14285714 | J6: 0.14285714 | K6: 0.16666667 | L6: 0.16666667 | M6: 0.16666667 | N6: 0.16666667 | O6: 0.16666667 | P6: 0.16666667 | Q6: 0.16666667 | R6: 0.16666667 | S6: 0.16666667 | T6: 0.16666667 | U6: 0.16666667 | V6: 0.16666667 | W6: 0.16666667 | X6: 0.16666667 | Y6: 0.16666667 | Z6: 0.03125 | AA6: 0.03125 | AB6: 0.03125 | AC6: 0.14285714 | AD6: 0.14285714 | AE6: 0.14285714 | AF6: 0.1 | AG6: 0.1 | AH6: 0.1 | AI6: 0.14285714 | AJ6: 0.14285714 | AK6: 0.14285714 | AM6: Boot | AN6: 10
A7: Tire | B7: 0.125 | C7: 0.125 | D7: 0.125 | E7: 0.125 | F7: 0.125 | G7: 0.125 | H7: 0.14285714 | I7: 0.14285714 | J7: 0.14285714 | K7: 0.16666667 | L7: 0.16666667 | M7: 0.16666667 | N7: 0.16666667 | O7: 0.16666667 | P7: 0.16666667 | Q7: 0.16666667 | R7: 0.16666667 | S7: 0.16666667 | T7: 0.16666667 | U7: 0.16666667 | V7: 0.16666667 | W7: 0.16666667 | X7: 0.16666667 | Y7: 0.16666667 | Z7: 0.03125 | AA7: 0.03125 | AB7: 0.03125 | AC7: 0.14285714 | AD7: 0.14285714 | AE7: 0.14285714 | AF7: 0.1 | AG7: 0.1 | AH7: 0.1 | AI7: 0.14285714 | AJ7: 0.14285714 | AK7: 0.14285714 | AM7: Tire | AN7: 10
A8: Stone | B8: 0.25 | C8: 0.25 | D8: 0.25 | E8: 0.25 | F8: 0.25 | G8: 0.25 | H8: 0.28571429 | I8: 0.28571429 | J8: 0.28571429 | K8: 0.33333333 | L8: 0.33333333 | M8: 0.33333333 | N8: 0.33333333 | O8: 0.33333333 | P8: 0.33333333 | Q8: 0.33333333 | R8: 0.33333333 | S8: 0.33333333 | T8: 0.33333333 | U8: 0.33333333 | V8: 0.33333333 | W8: 0.33333333 | X8: 0.33333333 | Y8: 0.33333333 | Z8: 0.0625 | AA8: 0.0625 | AB8: 0.0625 | AC8: 0.28571429 | AD8: 0.28571429 | AE8: 0.28571429 | AF8: 0.2 | AG8: 0.2 | AH8: 0.2 | AI8: 0.28571429 | AJ8: 0.28571429 | AK8: 0.28571429 | AM8: Stone | AN8: 10

Sheet Mouth of River (Expected Prices
B1: Jan 9a-4p | C1: Jan 4a-9a 4p-9p | D1: Jan 9p-4a | E1: Feb 9a-4p | F1: Feb 4a-9a 4p-9p | G1: Feb 9p-4a | H1: Mar 9a-4p | I1: Mar 4a-9a 4p-9p | J1: Mar 9p-4a | K1: Apr 9a-4p | L1: Apr 4a-9a 4p-9p | M1: Apr 9p-4a | N1: May 9a-4p | O1: May 4a-9a 4p-9p | P1: May 9p-4a | Q1: Jun 9a-4p | R1: Jun 4a-9a 4p-9p | S1: Jun 9p-4a | T1: Jul 9a-4p | U1: Jul 4a-9a 4p-9p | V1: Jul 9p-4a | W1: Aug 9a-4p | X1: Aug 4a-9a 4p-9p | Y1: Aug 9p-4a | Z1: Sep 9a-4p | AA1: Sep 4a-9a 4p-9p | AB1: Sep 9p-4a | AC1: Oct 9a-4p | AD1: Oct 4a-9a 4p-9p | AE1: Oct 9p-4a | AF1: Nov 9a-4p | AG1: Nov 4a-9a 4p-9p | AH1: Nov 9p-4a | AI1: Dec 9a-4p | AJ1: Dec 4a-9a 4p-9p | AK1: Dec 9p-4a
A2: Kingsalmon | B2: {=N('Mouth of River (Adjusted)'!B2:AK8) * N('Mouth of River (Adjusted)'!AN2:AN8)} -> 0 | C2: 0 | D2: 0 | E2: 0 | F2: 0 | G2: 0 | H2: 0 | I2: 0 | J2: 0 | K2: 0 | L2: 0 | M2: 0 | N2: 0 | O2: 0 | P2: 0 | Q2: 0 | R2: 0 | S2: 0 | T2: 0 | U2: 0 | V2: 0 | W2: 0 | X2: 0 | Y2: 0 | Z2: 281.25 | AA2: 281.25 | AB2: 281.25 | AC2: 0 | AD2: 0 | AE2: 0 | AF2: 0 | AG2: 0 | AH2: 0 | AI2: 0 | AJ2: 0 | AK2: 0
A3: Salmon | B3: 0 | C3: 0 | D3: 0 | E3: 0 | F3: 0 | G3: 0 | H3: 0 | I3: 0 | J3: 0 | K3: 0 | L3: 0 | M3: 0 | N3: 0 | O3: 0 | P3: 0 | Q3: 0 | R3: 0 | S3: 0 | T3: 0 | U3: 0 | V3: 0 | W3: 0 | X3: 0 | Y3: 0 | Z3: 437.5 | AA3: 437.5 | AB3: 437.5 | AC3: 0 | AD3: 0 | AE3: 0 | AF3: 0 | AG3: 0 | AH3: 0 | AI3: 0 | AJ3: 0 | AK3: 0
A4: Sturgeon | B4: 2500 | C4: 2500 | D4: 2500 | E4: 2500 | F4: 2500 | G4: 2500 | H4: 1428.5714 | I4: 1428.5714 | J4: 1428.5714 | K4: 0 | L4: 0 | M4: 0 | N4: 0 | O4: 0 | P4: 0 | Q4: 0 | R4: 0 | S4: 0 | T4: 0 | U4: 0 | V4: 0 | W4: 0 | X4: 0 | Y4: 0 | Z4: 312.5 | AA4: 312.5 | AB4: 312.5 | AC4: 1428.5714 | AD4: 1428.5714 | AE4: 1428.5714 | AF4: 4000 | AG4: 4000 | AH4: 4000 | AI4: 1428.5714 | AJ4: 1428.5714 | AK4: 1428.5714
A5: Can | B5: 2.5 | C5: 2.5 | D5: 2.5 | E5: 2.5 | F5: 2.5 | G5: 2.5 | H5: 2.8571429 | I5: 2.8571429 | J5: 2.8571429 | K5: 3.3333333 | L5: 3.3333333 | M5: 3.3333333 | N5: 3.3333333 | O5: 3.3333333 | P5: 3.3333333 | Q5: 3.3333333 | R5: 3.3333333 | S5: 3.3333333 | T5: 3.3333333 | U5: 3.3333333 | V5: 3.3333333 | W5: 3.3333333 | X5: 3.3333333 | Y5: 3.3333333 | Z5: 0.625 | AA5: 0.625 | AB5: 0.625 | AC5: 2.8571429 | AD5: 2.8571429 | AE5: 2.8571429 | AF5: 2 | AG5: 2 | AH5: 2 | AI5: 2.8571429 | AJ5: 2.8571429 | AK5: 2.8571429
A6: Boot | B6: 1.25 | C6: 1.25 | D6: 1.25 | E6: 1.25 | F6: 1.25 | G6: 1.25 | H6: 1.4285714 | I6: 1.4285714 | J6: 1.4285714 | K6: 1.6666667 | L6: 1.6666667 | M6: 1.6666667 | N6: 1.6666667 | O6: 1.6666667 | P6: 1.6666667 | Q6: 1.6666667 | R6: 1.6666667 | S6: 1.6666667 | T6: 1.6666667 | U6: 1.6666667 | V6: 1.6666667 | W6: 1.6666667 | X6: 1.6666667 | Y6: 1.6666667 | Z6: 0.3125 | AA6: 0.3125 | AB6: 0.3125 | AC6: 1.4285714 | AD6: 1.4285714 | AE6: 1.4285714 | AF6: 1 | AG6: 1 | AH6: 1 | AI6: 1.4285714 | AJ6: 1.4285714 | AK6: 1.4285714
A7: Tire | B7: 1.25 | C7: 1.25 | D7: 1.25 | E7: 1.25 | F7: 1.25 | G7: 1.25 | H7: 1.4285714 | I7: 1.4285714 | J7: 1.4285714 | K7: 1.6666667 | L7: 1.6666667 | M7: 1.6666667 | N7: 1.6666667 | O7: 1.6666667 | P7: 1.6666667 | Q7: 1.6666667 | R7: 1.6666667 | S7: 1.6666667 | T7: 1.6666667 | U7: 1.6666667 | V7: 1.6666667 | W7: 1.6666667 | X7: 1.6666667 | Y7: 1.6666667 | Z7: 0.3125 | AA7: 0.3125 | AB7: 0.3125 | AC7: 1.4285714 | AD7: 1.4285714 | AE7: 1.4285714 | AF7: 1 | AG7: 1 | AH7: 1 | AI7: 1.4285714 | AJ7: 1.4285714 | AK7: 1.4285714
A8: Stone | B8: 2.5 | C8: 2.5 | D8: 2.5 | E8: 2.5 | F8: 2.5 | G8: 2.5 | H8: 2.8571429 | I8: 2.8571429 | J8: 2.8571429 | K8: 3.3333333 | L8: 3.3333333 | M8: 3.3333333 | N8: 3.3333333 | O8: 3.3333333 | P8: 3.3333333 | Q8: 3.3333333 | R8: 3.3333333 | S8: 3.3333333 | T8: 3.3333333 | U8: 3.3333333 | V8: 3.3333333 | W8: 3.3333333 | X8: 3.3333333 | Y8: 3.3333333 | Z8: 0.625 | AA8: 0.625 | AB8: 0.625 | AC8: 2.8571429 | AD8: 2.8571429 | AE8: 2.8571429 | AF8: 2 | AG8: 2 | AH8: 2 | AI8: 2.8571429 | AJ8: 2.8571429 | AK8: 2.8571429
A9: Expected Profit Per Catch | B9: =SUM(B1:B8) -> 2507.5 | C9: =SUM(C1:C8) -> 2507.5 | D9: =SUM(D1:D8) -> 2507.5 | E9: =SUM(E1:E8) -> 2507.5 | F9: =SUM(F1:F8) -> 2507.5 | G9: =SUM(G1:G8) -> 2507.5 | H9: =SUM(H1:H8) -> 1437.1429 | I9: =SUM(I1:I8) -> 1437.1429 | ... AK9: =SUM(AK1:AK8) -> 1437.1429

Sheet Pond (Original Data)
B1: Jan 9a-4p | C1: Jan 4a-9a 4p-9p | D1: Jan 9p-4a | E1: Feb 9a-4p | F1: Feb 4a-9a 4p-9p | G1: Feb 9p-4a | H1: Mar 9a-4p | I1: Mar 4a-9a 4p-9p | J1: Mar 9p-4a | K1: Apr 9a-4p | L1: Apr 4a-9a 4p-9p | M1: Apr 9p-4a | N1: May 9a-4p | O1: May 4a-9a 4p-9p | P1: May 9p-4a | Q1: Jun 9a-4p | R1: Jun 4a-9a 4p-9p | S1: Jun 9p-4a | T1: Jul 9a-4p | U1: Jul 4a-9a 4p-9p | V1: Jul 9p-4a | W1: Aug 9a-4p | X1: Aug 4a-9a 4p-9p | Y1: Aug 9p-4a | Z1: Sep 9a-4p | AA1: Sep 4a-9a 4p-9p | AB1: Sep 9p-4a | AC1: Oct 9a-4p | AD1: Oct 4a-9a 4p-9p | AE1: Oct 9p-4a | AF1: Nov 9a-4p | AG1: Nov 4a-9a 4p-9p | AH1: Nov 9p-4a | AI1: Dec 9a-4p | AJ1: Dec 4a-9a 4p-9p | AK1: Dec 9p-4a
A2: Carp | B2: 8 | C2: 8 | D2: 8 | E2: 8 | F2: 8 | G2: 8 | H2: 7 | I2: 8 | J2: 8 | K2: 7 | L2: 9 | M2: 8 | N2: 6 | O2: 6 | P2: 7 | Q2: 6 | R2: 6 | S2: 6 | T2: 6 | U2: 6 | V2: 6 | W2: 6 | X2: 6 | Y2: 6 | Z2: 3 | AA2: 3 | AB2: 3 | AC2: 8 | AD2: 8 | AE2: 8 | AF2: 8 | AG2: 7 | AH2: 7 | AI2: 6 | AJ2: 6 | AK2: 6
A3: Catfish | B3: 0 | C3: 0 | D3: 0 | E3: 0 | F3: 0 | G3: 0 | H3: 0 | I3: 0 | J3: 0 | K3: 0 | L3: 0 | M3: 0 | N3: 0 | O3: 7 | P3: 7 | Q3: 0 | R3: 7 | S3: 7 | T3: 0 | U3: 8 | V3: 8 | W3: 0 | X3: 8 | Y3: 8 | Z3: 0 | AA3: 7 | AB3: 6 | AC3: 0 | AD3: 8 | AE3: 8 | AF3: 0 | AG3: 0 | AH3: 0 | AI3: 0 | AJ3: 0 | AK3: 0
A4: Crawfish | B4: 0 | C4: 0 | D4: 0 | E4: 0 | F4: 0 | G4: 0 | H4: 0 | I4: 0 | J4: 0 | K4: 12 | L4: 11 | M4: 11 | N4: 10 | O4: 9 | P4: 9 | Q4: 10 | R4: 8 | S4: 8 | T4: 8 | U4: 9 | V4: 7 | W4: 10 | X4: 9 | Y4: 8 | Z4: 4 | AA4: 4 | AB4: 4 | AC4: 0 | AD4: 0 | AE4: 0 | AF4: 0 | AG4: 0 | AH4: 0 | AI4: 0 | AJ4: 0 | AK4: 0
A5: Frog | B5: 0 | C5: 0 | D5: 0 | E5: 0 | F5: 0 | G5: 0 | H5: 0 | I5: 0 | J5: 0 | K5: 0 | L5: 0 | M5: 0 | N5: 9 | O5: 8 | P5: 8 | Q5: 9 | R5: 9 | S5: 7 | T5: 8 | U5: 9 | V5: 9 | W5: 8 | X5: 8 | Y5: 7 | Z5: 0 | AA5: 0 | AB5: 0 | AC5: 0 | AD5: 0 | AE5: 0 | AF5: 0 | AG5: 0 | AH5: 0 | AI5: 0 | AJ5: 0 | AK5: 0
A6: Gar | B6: 0 | C6: 0 | D6: 0 | E6: 0 | F6: 0 | G6: 0 | H6: 0 | I6: 0 | J6: 0 | K6: 0 | L6: 0 | M6: 0 | N6: 0 | O6: 0 | P6: 0 | Q6: 0 | R6: 1 | S6: 2 | T6: 0 | U6: 1 | V6: 2 | W6: 0 | X6: 1 | Y6: 2 | Z6: 0 | AA6: 1 | AB6: 2 | AC6: 0 | AD6: 0 | AE6: 0 | AF6: 0 | AG6: 0 | AH6: 0 | AI6: 0 | AJ6: 0 | AK6: 0
A7: Giant Snakehead | B7: 0 | C7: 0 | D7: 0 | E7: 0 | F7: 0 | G7: 0 | H7: 0 | I7: 0 | J7: 0 | K7: 0 | L7: 0 | M7: 0 | N7: 0 | O7: 0 | P7: 0 | Q7: 2 | R7: 0 | S7: 0 | T7: 2 | U7: 0 | V7: 0 | W7: 2 | X7: 0 | Y7: 0 | Z7: 0 | AA7: 0 | AB7: 0 | AC7: 0 | AD7: 0 | AE7: 0 | AF7: 0 | AG7: 0 | AH7: 0 | AI7: 0 | AJ7: 0 | AK7: 0
A8: Goldfish | B8: 3 | C8: 4 | D8: 4 | E8: 3 | F8: 4 | G8: 4 | H8: 2 | I8: 3 | J8: 2 | K8: 2 | L8: 2 | M8: 2 | N8: 2 | O8: 2 | P8: 2 | Q8: 2 | R8: 2 | S8: 2 | T8: 2 | U8: 2 | V8: 2 | W8: 2 | X8: 2 | Y8: 2 | Z8: 2 | AA8: 1 | AB8: 1 | AC8: 2 | AD8: 2 | AE8: 2 | AF8: 2 | AG8: 2 | AH8: 2 | AI8: 3 | AJ8: 3 | AK8: 3
A9: Killifish | B9: 0 | C9: 0 | D9: 0 | E9: 0 | F9: 0 | G9: 0 | H9: 0 | I9: 0 | J9: 0 | K9: 4 | L9: 4 | M9: 4 | N9: 3 | O9: 3 | P9: 3 | Q9: 3 | R9: 3 | S9: 3 | T9: 3 | U9: 3 | V9: 3 | W9: 3 | X9: 3 | Y9: 3 | Z9: 0 | AA9: 0 | AB9: 0 | AC9: 0 | AD9: 0 | AE9: 0 | AF9: 0 | AG9: 0 | AH9: 0 | AI9: 0 | AJ9: 0 | AK9: 0
A10: Koi | B10: 0 | C10: 3 | D10: 3 | E10: 0 | F10: 3 | G10: 3 | H10: 0 | I10: 3 | J10: 3 | K10: 0 | L10: 3 | M10: 3 | N10: 0 | O10: 1 | P10: 2 | Q10: 0 | R10: 2 | S10: 2 | T10: 0 | U10: 2 | V10: 2 | W10: 0 | X10: 2 | Y10: 2 | Z10: 0 | AA10: 1 | AB10: 1 | AC10: 0 | AD10: 3 | AE10: 3 | AF10: 0 | AG10: 2 | AH10: 2 | AI10: 0 | AJ10: 4 | AK10: 4
A11: Pop-Eyed Goldfish | B11: 1 | C11: 0 | D11: 0 | E11: 1 | F11: 0 | G11: 0 | H11: 2 | I11: 0 | J11: 0 | K11: 2 | L11: 0 | M11: 0 | N11: 1 | O11: 0 | P11: 0 | Q11: 1 | R11: 0 | S11: 0 | T11: 1 | U11: 0 | V11: 0 | W11: 1 | X11: 0 | Y11: 0 | Z11: 1 | AA11: 0 | AB11: 0 | AC11: 2 | AD11: 0 | AE11: 0 | AF11: 2 | AG11: 0 | AH11: 0 | AI11: 2 | AJ11: 0 | AK11: 0
A12: Ranchu Goldfish | B12: 1 | C12: 0 | D12: 0 | E12: 1 | F12: 0 | G12: 0 | H12: 1 | I12: 0 | J12: 0 | K12: 1 | L12: 0 | M12: 0 | N12: 1 | O12: 0 | P12: 0 | Q12: 1 | R12: 0 | S12: 0 | T12: 1 | U12: 0 | V12: 0 | W12: 1 | X12: 0 | Y12: 0 | Z12: 1 | AA12: 0 | AB12: 0 | AC12: 2 | AD12: 0 | AE12: 0 | AF12: 2 | AG12: 0 | AH12: 0 | AI12: 2 | AJ12: 0 | AK12: 0
A13: Tadpole | B13: 0 | C13: 0 | D13: 0 | E13: 0 | F13: 0 | G13: 0 | H13: 6 | I13: 5 | J13: 6 | K13: 6 | L13: 6 | M13: 6 | N13: 5 | O13: 5 | P13: 5 | Q13: 5 | R13: 5 | S13: 5 | T13: 5 | U13: 5 | V13: 5 | W13: 0 | X13: 0 | Y13: 0 | Z13: 0 | AA13: 0 | AB13: 0 | AC13: 0 | AD13: 0 | AE13: 0 | AF13: 0 | AG13: 0 | AH13: 0 | AI13: 0 | AJ13: 0 | AK13: 0
... A17: Stone | B17: 2 | C17: 2 | D17: 2 | E17: 2 | F17: 2 | G17: 2 | H17: 2 | I17: 2 | J17: 2 | K17: 2 | L17: 2 | M17: 2 | N17: 2 | O17: 2 | P17: 2 | Q17: 2 | R17: 2 | S17: 2 | T17: 2 | U17: 2 | V17: 2 | W17: 2 | X17: 2 | Y17: 2 | Z17: 2 | AA17: 2 | AB17: 2 | AC17: 2 | AD17: 2 | AE17: 2 | AF17: 2 | AG17: 2 | AH17: 2 | AI17: 2 | AJ17: 2 | AK17: 2

Sheet Pond (Adjusted)
B1: Jan 9a-4p | C1: Jan 4a-9a 4p-9p | D1: Jan 9p-4a | E1: Feb 9a-4p | F1: Feb 4a-9a 4p-9p | G1: Feb 9p-4a | H1: Mar 9a-4p | I1: Mar 4a-9a 4p-9p | J1: Mar 9p-4a | K1: Apr 9a-4p | L1: Apr 4a-9a 4p-9p | M1: Apr 9p-4a | N1: May 9a-4p | O1: May 4a-9a 4p-9p | P1: May 9p-4a | Q1: Jun 9a-4p | R1: Jun 4a-9a 4p-9p | S1: Jun 9p-4a | T1: Jul 9a-4p | U1: Jul 4a-9a 4p-9p | V1: Jul 9p-4a | W1: Aug 9a-4p | X1: Aug 4a-9a 4p-9p | Y1: Aug 9p-4a | Z1: Sep 9a-4p | AA1: Sep 4a-9a 4p-9p | AB1: Sep 9p-4a | AC1: Oct 9a-4p | AD1: Oct 4a-9a 4p-9p | AE1: Oct 9p-4a | AF1: Nov 9a-4p | AG1: Nov 4a-9a 4p-9p | AH1: Nov 9p-4a | AI1: Dec 9a-4p | AJ1: Dec 4a-9a 4p-9p | AK1: Dec 9p-4a | AN1: Price
A2: Carp | B2: {=IF( 'Pond (Original Data)'!B2:AK32 = "", "", 'Pond (Original Data)'!B2:AK32 / (MMULT(TRANSPOSE(SIGN(ROW('Pond (Original Data)'!B2:AK32))), N('Pond (Original Data)'!B2:AK32))) )} -> 0.42105263 | C2: 0.38095238 | D2: 0.38095238 | E2: 0.42105263 | F2: 0.38095238 | G2: 0.38095238 | H2: 0.29166667 | I2: 0.32 | J2: 0.32 | K2: 0.175 | L2: 0.2195122 | M2: 0.2 | N2: 0.13953488 | O2: 0.12765957 | P2: 0.14285714 | Q2: 0.13333333 | R2: 0.12244898 | S2: 0.125 | T2: 0.14285714 | U2: 0.11764706 | V2: 0.12 | W2: 0.15384615 | X2: 0.13333333 | Y2: 0.13636364 | Z2: 0.17647059 | AA2: 0.13043478 | AB2: 0.13043478 | AC2: 0.4 | AD2: 0.2962963 | AE2: 0.2962963 | AF2: 0.4 | AG2: 0.41176471 | AH2: 0.41176471 | AI2: 0.31578947 | AJ2: 0.31578947 | AK2: 0.31578947 | AM2: Carp | AN2: 300
A3: Catfish | B3: 0 | C3: 0 | D3: 0 | E3: 0 | F3: 0 | G3: 0 | H3: 0 | I3: 0 | J3: 0 | K3: 0 | L3: 0 | M3: 0 | N3: 0 | O3: 0.14893617 | P3: 0.14285714 | Q3: 0 | R3: 0.14285714 | S3: 0.14583333 | T3: 0 | U3: 0.15686275 | V3: 0.16 | W3: 0 | X3: 0.17777778 | Y3: 0.18181818 | Z3: 0 | AA3: 0.30434783 | AB3: 0.26086957 | AC3: 0 | AD3: 0.2962963 | AE3: 0.2962963 | AF3: 0 | AG3: 0 | AH3: 0 | AI3: 0 | AJ3: 0 | AK3: 0 | AM3: Catfish | AN3: 800
A4: Crawfish | B4: 0 | C4: 0 | D4: 0 | E4: 0 | F4: 0 | G4: 0 | H4: 0 | I4: 0 | J4: 0 | K4: 0.3 | L4: 0.26829268 | M4: 0.275 | N4: 0.23255814 | O4: 0.19148936 | P4: 0.18367347 | Q4: 0.22222222 | R4: 0.16326531 | S4: 0.16666667 | T4: 0.19047619 | U4: 0.17647059 | V4: 0.14 | W4: 0.25641026 | X4: 0.2 | Y4: 0.18181818 | Z4: 0.23529412 | AA4: 0.17391304 | AB4: 0.17391304 | AC4: 0 | AD4: 0 | AE4: 0 | AF4: 0 | AG4: 0 | AH4: 0 | AI4: 0 | AJ4: 0 | AK4: 0 | AM4: Crawfish | AN4: 200
A5: Frog | B5: 0 | C5: 0 | D5: 0 | E5: 0 | F5: 0 | G5: 0 | H5: 0 | I5: 0 | J5: 0 | K5: 0 | L5: 0 | M5: 0 | N5: 0.20930233 | O5: 0.17021277 | P5: 0.16326531 | Q5: 0.2 | R5: 0.18367347 | S5: 0.14583333 | T5: 0.19047619 | U5: 0.17647059 | V5: 0.18 | W5: 0.20512821 | X5: 0.17777778 | Y5: 0.15909091 | Z5: 0 | AA5: 0 | AB5: 0 | AC5: 0 | AD5: 0 | AE5: 0 | AF5: 0 | AG5: 0 | AH5: 0 | AI5: 0 | AJ5: 0 | AK5: 0 | AM5: Frog | AN5: 120
A6: Gar | B6: 0 | C6: 0 | D6: 0 | E6: 0 | F6: 0 | G6: 0 | H6: 0 | I6: 0 | J6: 0 | K6: 0 | L6: 0 | M6: 0 | N6: 0 | O6: 0 | P6: 0 | Q6: 0 | R6: 0.020408163 | S6: 0.041666667 | T6: 0 | U6: 0.019607843 | V6: 0.04 | W6: 0 | X6: 0.022222222 | Y6: 0.045454545 | Z6: 0 | AA6: 0.043478261 | AB6: 0.086956522 | AC6: 0 | AD6: 0 | AE6: 0 | AF6: 0 | AG6: 0 | AH6: 0 | AI6: 0 | AJ6: 0 | AK6: 0 | AM6: Gar | AN6: 6000
A7: Giant Snakehead | B7: 0 | C7: 0 | D7: 0 | E7: 0 | F7: 0 | G7: 0 | H7: 0 | I7: 0 | J7: 0 | K7: 0 | L7: 0 | M7: 0 | N7: 0 | O7: 0 | P7: 0 | Q7: 0.044444444 | R7: 0 | S7: 0 | T7: 0.047619048 | U7: 0 | V7: 0 | W7: 0.051282051 | X7: 0 | Y7: 0 | Z7: 0 | AA7: 0 | AB7: 0 | AC7: 0 | AD7: 0 | AE7: 0 | AF7: 0 | AG7: 0 | AH7: 0 | AI7: 0 | AJ7: 0 | AK7: 0 | AM7: Giant Snakehead | AN7: 5500
A8: Goldfish | B8: 0.15789474 | C8: 0.19047619 | D8: 0.19047619 | E8: 0.15789474 | F8: 0.19047619 | G8: 0.19047619 | H8: 0.083333333 | I8: 0.12 | J8: 0.08 | K8: 0.05 | L8: 0.048780488 | M8: 0.05 | N8: 0.046511628 | O8: 0.042553191 | P8: 0.040816327 | Q8: 0.044444444 | R8: 0.040816327 | S8: 0.041666667 | T8: 0.047619048 | U8: 0.039215686 | V8: 0.04 | W8: 0.051282051 | X8: 0.044444444 | Y8: 0.045454545 | Z8: 0.11764706 | AA8: 0.043478261 | AB8: 0.043478261 | AC8: 0.1 | AD8: 0.074074074 | AE8: 0.074074074 | AF8: 0.1 | AG8: 0.11764706 | AH8: 0.11764706 | AI8: 0.15789474 | AJ8: 0.15789474 | AK8: 0.15789474 | AM8: Goldfish | AN8: 1300
A9: Killifish | B9: 0 | C9: 0 | D9: 0 | E9: 0 | F9: 0 | G9: 0 | H9: 0 | I9: 0 | J9: 0 | K9: 0.1 | L9: 0.097560976 | M9: 0.1 | N9: 0.069767442 | O9: 0.063829787 | P9: 0.06122449 | Q9: 0.066666667 | R9: 0.06122449 | S9: 0.0625 | T9: 0.071428571 | U9: 0.058823529 | V9: 0.06 | W9: 0.076923077 | X9: 0.066666667 | Y9: 0.068181818 | Z9: 0 | AA9: 0 | AB9: 0 | AC9: 0 | AD9: 0 | AE9: 0 | AF9: 0 | AG9: 0 | AH9: 0 | AI9: 0 | AJ9: 0 | AK9: 0 | AM9: Killifish | AN9: 300
A10: Koi | B10: 0 | C10: 0.14285714 | D10: 0.14285714 | E10: 0 | F10: 0.14285714 | G10: 0.14285714 | H10: 0 | I10: 0.12 | J10: 0.12 | K10: 0 | L10: 0.073170732 | M10: 0.075 | N10: 0 | O10: 0.021276596 | P10: 0.040816327 | Q10: 0 | R10: 0.040816327 | S10: 0.041666667 | T10: 0 | U10: 0.039215686 | V10: 0.04 | W10: 0 | X10: 0.044444444 | Y10: 0.045454545 | Z10: 0 | AA10: 0.043478261 | AB10: 0.043478261 | AC10: 0 | AD10: 0.11111111 | AE10: 0.11111111 | AF10: 0 | AG10: 0.11764706 | AH10: 0.11764706 | AI10: 0 | AJ10: 0.21052632 | AK10: 0.21052632 | AM10: Koi | AN10: 4000
A11: Pop-Eyed Goldfish | B11: 0.052631579 | C11: 0 | D11: 0 | E11: 0.052631579 | F11: 0 | G11: 0 | H11: 0.083333333 | I11: 0 | J11: 0 | K11: 0.05 | L11: 0 | M11: 0 | N11: 0.023255814 | O11: 0 | P11: 0 | Q11: 0.022222222 | R11: 0 | S11: 0 | T11: 0.023809524 | U11: 0 | V11: 0 | W11: 0.025641026 | X11: 0 | Y11: 0 | Z11: 0.058823529 | AA11: 0 | AB11: 0 | AC11: 0.1 | AD11: 0 | AE11: 0 | AF11: 0.1 | AG11: 0 | AH11: 0 | AI11: 0.10526316 | AJ11: 0 | AK11: 0 | AM11: Pop-Eyed Goldfish | AN11: 1300
A12: Ranchu Goldfish | B12: 0.052631579 | C12: 0 | D12: 0 | E12: 0.052631579 | F12: 0 | G12: 0 | H12: 0.041666667 | I12: 0 | J12: 0 | K12: 0.025 | L12: 0 | M12: 0 | N12: 0.023255814 | O12: 0 | P12: 0 | Q12: 0.022222222 | R12: 0 | S12: 0 | T12: 0.023809524 | U12: 0 | V12: 0 | W12: 0.025641026 | X12: 0 | Y12: 0 | Z12: 0.058823529 | AA12: 0 | AB12: 0 | AC12: 0.1 | AD12: 0 | AE12: 0 | AF12: 0.1 | AG12: 0 | AH12: 0 | AI12: 0.10526316 | AJ12: 0 | AK12: 0 | AM12: Ranchu Goldfish | AN12: 4500
A13: Tadpole | B13: 0 | C13: 0 | D13: 0 | E13: 0 | F13: 0 | G13: 0 | H13: 0.25 | I13: 0.2 | J13: 0.24 | K13: 0.15 | L13: 0.14634146 | M13: 0.15 | N13: 0.11627907 | O13: 0.10638298 | P13: 0.10204082 | Q13: 0.11111111 | R13: 0.10204082 | S13: 0.10416667 | T13: 0.11904762 | U13: 0.098039216 | V13: 0.1 | W13: 0 | X13: 0 | Y13: 0 | Z13: 0 | AA13: 0 | AB13: 0 | AC13: 0 | AD13: 0 | AE13: 0 | AF13: 0 | AG13: 0 | AH13: 0 | AI13: 0 | AJ13: 0 | AK13: 0 | AM13: Tadpole | AN13: 100
A14: Can | B14: 0.10526316 | C14: 0.095238095 | D14: 0.095238095 | E14: 0.10526316 | F14: 0.095238095 | G14: 0.095238095 | H14: 0.083333333 | I14: 0.08 | J14: 0.08 | K14: 0.05 | L14: 0.048780488 | M14: 0.05 | N14: 0.046511628 | O14: 0.042553191 | P14: 0.040816327 | Q14: 0.044444444 | R14: 0.040816327 | S14: 0.041666667 | T14: 0.047619048 | U14: 0.039215686 | V14: 0.04 | W14: 0.051282051 | X14: 0.044444444 | Y14: 0.045454545 | Z14: 0.11764706 | AA14: 0.086956522 | AB14: 0.086956522 | AC14: 0.1 | AD14: 0.074074074 | AE14: 0.074074074 | AF14: 0.1 | AG14: 0.11764706 | AH14: 0.11764706 | AI14: 0.10526316 | AJ14: 0.10526316 | AK14: 0.10526316 | AM14: Can | AN14: 10
... A17: Stone | B17: 0.10526316 | C17: 0.095238095 | D17: 0.095238095 | E17: 0.10526316 | F17: 0.095238095 | G17: 0.095238095 | H17: 0.083333333 | I17: 0.08 | J17: 0.08 | K17: 0.05 | L17: 0.048780488 | M17: 0.05 | N17: 0.046511628 | O17: 0.042553191 | P17: 0.040816327 | Q17: 0.044444444 | R17: 0.040816327 | S17: 0.041666667 | T17: 0.047619048 | U17: 0.039215686 | V17: 0.04 | W17: 0.051282051 | X17: 0.044444444 | Y17: 0.045454545 | Z17: 0.11764706 | AA17: 0.086956522 | AB17: 0.086956522 | AC17: 0.1 | AD17: 0.074074074 | AE17: 0.074074074 | AF17: 0.1 | AG17: 0.11764706 | AH17: 0.11764706 | AI17: 0.10526316 | AJ17: 0.10526316 | AK17: 0.10526316 | AM17: Stone | AN17: 10

Sheet Pond (Expected Prices)
B1: Jan 9a-4p | C1: Jan 4a-9a 4p-9p | D1: Jan 9p-4a | E1: Feb 9a-4p | F1: Feb 4a-9a 4p-9p | G1: Feb 9p-4a | H1: Mar 9a-4p | I1: Mar 4a-9a 4p-9p | J1: Mar 9p-4a | K1: Apr 9a-4p | L1: Apr 4a-9a 4p-9p | M1: Apr 9p-4a | N1: May 9a-4p | O1: May 4a-9a 4p-9p | P1: May 9p-4a | Q1: Jun 9a-4p | R1: Jun 4a-9a 4p-9p | S1: Jun 9p-4a | T1: Jul 9a-4p | U1: Jul 4a-9a 4p-9p | V1: Jul 9p-4a | W1: Aug 9a-4p | X1: Aug 4a-9a 4p-9p | Y1: Aug 9p-4a | Z1: Sep 9a-4p | AA1: Sep 4a-9a 4p-9p | AB1: Sep 9p-4a | AC1: Oct 9a-4p | AD1: Oct 4a-9a 4p-9p | AE1: Oct 9p-4a | AF1: Nov 9a-4p | AG1: Nov 4a-9a 4p-9p | AH1: Nov 9p-4a | AI1: Dec 9a-4p | AJ1: Dec 4a-9a 4p-9p | AK1: Dec 9p-4a
